<?xml version="1.0" ?>
<!-- =================================================================================== -->
<!-- |    This document was autogenerated by xacro from /home/neal/ws_humble/src/human_description/robots/M92UW/M92UW.urdf.xacro | -->
<!-- |    EDITING THIS FILE BY HAND IS NOT RECOMMENDED                                 | -->
<!-- =================================================================================== -->
<robot name="M92UW">
  <link name="base_footprint">
            </link>
  <joint name="base_footprint_fixed_joint" type="fixed">
    <parent link="base_footprint"/>
    <child link="base_link"/>
    <origin rpy="0 0 0" xyz="0 0 0.1"/>
  </joint>
  <link name="base_link">
    <visual name="base_link_vis">
      <geometry>
        <mesh filename="package://human_description/meshes/M92UW/visual/base_link.stl" scale="1e-3 1e-3 1e-3"/>
      </geometry>
      <material name="metal">
        <color rgba="0.85 0.85 0.85 1"/>
      </material>
    </visual>
    <collision name="base_link_col">
      <geometry>
        <mesh filename="package://human_description/meshes/M92UW/collision/base_link.stl" scale="1e-3 1e-3 1e-3"/>
      </geometry>
    </collision>
    <inertial>
      <origin rpy="0.0 0.0 0.0" xyz="0.013367658 0 -0.015095836"/>
      <mass value="74.786285"/>
      <inertia ixx="2.5701579" ixy="0" ixz="-0.015531692" iyy="2.4786102" iyz="0" izz="4.3899894"/>
    </inertial>
  </link>
  <link name="lf_wheel_link">
    <visual name="lf_wheel_link_vis">
      <geometry>
        <mesh filename="package://human_description/meshes/M92UW/visual/lf_wheel_link.stl" scale="1e-3 1e-3 1e-3"/>
      </geometry>
      <material name="carbon">
        <color rgba="1 1 1 1"/>
        <texture filename="package://human_description/textures/carbon.png"/>
      </material>
    </visual>
    <collision name="lf_wheel_link_col">
      <geometry>
        <mesh filename="package://human_description/meshes/M92UW/collision/lf_wheel_link.stl" scale="1e-3 1e-3 1e-3"/>
      </geometry>
    </collision>
    <inertial>
      <origin rpy="0.0 0.0 0.0" xyz="0 0.10966209 0"/>
      <mass value="1.1156517"/>
      <inertia ixx="0.0030579042" ixy="0" ixz="0" iyy="0.0050380481" iyz="0" izz="0.0030579069"/>
    </inertial>
  </link>
  <joint name="lf_wheel_joint" type="fixed">
    <parent link="base_link"/>
    <child link="lf_wheel_link"/>
    <origin rpy="0.0 0.0 0.0" xyz="0.29 0.12 -0.03"/>
    <axis xyz="0 1 0"/>
  </joint>
  <link name="lb_wheel_link">
    <visual name="lb_wheel_link_vis">
      <geometry>
        <mesh filename="package://human_description/meshes/M92UW/visual/lb_wheel_link.stl" scale="1e-3 1e-3 1e-3"/>
      </geometry>
      <material name="carbon">
        <color rgba="1 1 1 1"/>
        <texture filename="package://human_description/textures/carbon.png"/>
      </material>
    </visual>
    <collision name="lb_wheel_link_col">
      <geometry>
        <mesh filename="package://human_description/meshes/M92UW/collision/lb_wheel_link.stl" scale="1e-3 1e-3 1e-3"/>
      </geometry>
    </collision>
    <inertial>
      <origin rpy="0.0 0.0 0.0" xyz="0 0.10966209 0"/>
      <mass value="1.1156517"/>
      <inertia ixx="0.0030579042" ixy="0" ixz="0" iyy="0.0050380481" iyz="0" izz="0.0030579069"/>
    </inertial>
  </link>
  <joint name="lb_wheel_joint" type="fixed">
    <parent link="base_link"/>
    <child link="lb_wheel_link"/>
    <origin rpy="0.0 0.0 0.0" xyz="-0.29 0.12 -0.03"/>
    <axis xyz="0 1 0"/>
  </joint>
  <link name="rf_wheel_link">
    <visual name="rf_wheel_link_vis">
      <geometry>
        <mesh filename="package://human_description/meshes/M92UW/visual/rf_wheel_link.stl" scale="1e-3 1e-3 1e-3"/>
      </geometry>
      <material name="carbon">
        <color rgba="1 1 1 1"/>
        <texture filename="package://human_description/textures/carbon.png"/>
      </material>
    </visual>
    <collision name="rf_wheel_link_col">
      <geometry>
        <mesh filename="package://human_description/meshes/M92UW/collision/rf_wheel_link.stl" scale="1e-3 1e-3 1e-3"/>
      </geometry>
    </collision>
    <inertial>
      <origin rpy="0.0 0.0 0.0" xyz="0 -0.10966209 0"/>
      <mass value="1.1156517"/>
      <inertia ixx="0.0030579042" ixy="0" ixz="0" iyy="0.0050380481" iyz="0" izz="0.0030579069"/>
    </inertial>
  </link>
  <joint name="rf_wheel_joint" type="fixed">
    <parent link="base_link"/>
    <child link="rf_wheel_link"/>
    <origin rpy="0.0 0.0 0.0" xyz="0.29 -0.12 -0.03"/>
    <axis xyz="0 1 0"/>
  </joint>
  <link name="rb_wheel_link">
    <visual name="rb_wheel_link_vis">
      <geometry>
        <mesh filename="package://human_description/meshes/M92UW/visual/rb_wheel_link.stl" scale="1e-3 1e-3 1e-3"/>
      </geometry>
      <material name="carbon">
        <color rgba="1 1 1 1"/>
        <texture filename="package://human_description/textures/carbon.png"/>
      </material>
    </visual>
    <collision name="rb_wheel_link_col">
      <geometry>
        <mesh filename="package://human_description/meshes/M92UW/collision/rb_wheel_link.stl" scale="1e-3 1e-3 1e-3"/>
      </geometry>
    </collision>
    <inertial>
      <origin rpy="0.0 0.0 0.0" xyz="0 -0.10966209 0"/>
      <mass value="1.1156517"/>
      <inertia ixx="0.0030579042" ixy="0" ixz="0" iyy="0.0050380481" iyz="0" izz="0.0030579069"/>
    </inertial>
  </link>
  <joint name="rb_wheel_joint" type="fixed">
    <parent link="base_link"/>
    <child link="rb_wheel_link"/>
    <origin rpy="0.0 0.0 0.0" xyz="-0.29 -0.12 -0.03"/>
    <axis xyz="0 1 0"/>
  </joint>
  <link name="ankle_p_link">
    <visual name="ankle_p_link_vis">
      <geometry>
        <mesh filename="package://human_description/meshes/M92UW/visual/ankle_p_link.stl" scale="1e-3 1e-3 1e-3"/>
      </geometry>
      <material name="metal">
        <color rgba="0.85 0.85 0.85 1"/>
      </material>
    </visual>
    <collision name="ankle_p_link_col">
      <geometry>
        <mesh filename="package://human_description/meshes/M92UW/collision/ankle_p_link.stl" scale="1e-3 1e-3 1e-3"/>
      </geometry>
    </collision>
    <inertial>
      <origin rpy="0.0 0.0 0.0" xyz="0 0.00031353654 0.2"/>
      <mass value="5.0014729"/>
      <inertia ixx="0.12742424" ixy="0.0" ixz="0.0" iyy="0.11078527" iyz="0.0" izz="0.040523373"/>
    </inertial>
  </link>
  <joint name="ankle_p_joint" type="revolute">
    <parent link="base_link"/>
    <child link="ankle_p_link"/>
    <origin rpy="0.0 0.0 0.0" xyz="0.085 0.0 0.0"/>
    <axis xyz="0 1 0"/>
    <limit effort="436.0" lower="-1.5707963267948966" upper="0.05235987755982988" velocity="2.51"/>
    <safety_controller k_position="121.0" k_velocity="540.0" soft_lower_limit="-1.5184364492350666" soft_upper_limit="0.0"/>
    <dynamics damping="0.003" friction="0.2"/>
  </joint>
  <link name="knee_p_link">
    <visual name="knee_p_link_vis">
      <geometry>
        <mesh filename="package://human_description/meshes/M92UW/visual/knee_p_link.stl" scale="1e-3 1e-3 1e-3"/>
      </geometry>
      <material name="metal">
        <color rgba="0.85 0.85 0.85 1"/>
      </material>
    </visual>
    <collision name="knee_p_link_col">
      <geometry>
        <mesh filename="package://human_description/meshes/M92UW/collision/knee_p_link.stl" scale="1e-3 1e-3 1e-3"/>
      </geometry>
    </collision>
    <inertial>
      <origin rpy="0.0 0.0 0.0" xyz="-0.00017250466 -5.7499427e-05 0.091520826"/>
      <mass value="9.9995835"/>
      <inertia ixx="0.17718143" ixy="3.3078853e-07" ixz="0.00019537528" iyy="0.17966307" iyz="6.5114089e-05" izz="0.038209575"/>
    </inertial>
  </link>
  <joint name="knee_p_joint" type="revolute">
    <parent link="ankle_p_link"/>
    <child link="knee_p_link"/>
    <origin rpy="0.0 0.0 0.0" xyz="0.0 0.0 0.4"/>
    <axis xyz="0 1 0"/>
    <limit effort="436.0" lower="-0.05235987755982988" upper="2.7768188399229783" velocity="2.51"/>
    <safety_controller k_position="121.0" k_velocity="540.0" soft_lower_limit="0.0" soft_upper_limit="2.724458962363148"/>
    <dynamics damping="0.003" friction="0.2"/>
  </joint>
  <ros2_control name="leg_system" type="system">
    <hardware>
      <plugin>mujoco_ros2_control/MujocoSystem</plugin>
    </hardware>
    <joint name="ankle_p_joint">
      <param name="initial_position">0.0</param>
      <command_interface name="position"/>
      <state_interface name="position">
        <param name="initial_value">0.0</param>
      </state_interface>
      <state_interface name="velocity"/>
      <state_interface name="effort"/>
    </joint>
    <transmission name="ankle_p_transmission">
      <plugin>transmission_interface/SimpleTransmission</plugin>
      <joint name="ankle_p_joint" role="joint1">
        <mechanical_reduction>1.0</mechanical_reduction>
        <offset>0</offset>
      </joint>
      <actuator name="ankle_p_actuator" role="actuator1">
        <mechanical_reduction>1.0</mechanical_reduction>
        <offset>0</offset>
      </actuator>
    </transmission>
    <joint name="knee_p_joint">
      <param name="initial_position">0.0</param>
      <command_interface name="position"/>
      <state_interface name="position">
        <param name="initial_value">0.0</param>
      </state_interface>
      <state_interface name="velocity"/>
      <state_interface name="effort"/>
    </joint>
    <transmission name="knee_p_transmission">
      <plugin>transmission_interface/SimpleTransmission</plugin>
      <joint name="knee_p_joint" role="joint1">
        <mechanical_reduction>1.0</mechanical_reduction>
        <offset>0</offset>
      </joint>
      <actuator name="knee_p_actuator" role="actuator1">
        <mechanical_reduction>1.0</mechanical_reduction>
        <offset>0</offset>
      </actuator>
    </transmission>
  </ros2_control>
  <link name="waist1_p_link">
    <visual name="waist1_p_link_vis">
      <geometry>
        <mesh filename="package://human_description/meshes/M92UW/visual/waist1_p_link.stl" scale="1e-3 1e-3 1e-3"/>
      </geometry>
      <material name="metal">
        <color rgba="0.85 0.85 0.85 1"/>
      </material>
    </visual>
    <collision name="waist1_p_link_col">
      <geometry>
        <mesh filename="package://human_description/meshes/M92UW/collision/waist1_p_link.stl" scale="1e-3 1e-3 1e-3"/>
      </geometry>
    </collision>
    <inertial>
      <origin rpy="0.0 0.0 0.0" xyz="0 0 0.057429778"/>
      <mass value="6.3049221"/>
      <inertia ixx="0.029907033" ixy="0" ixz="0" iyy="0.031745346" iyz="0" izz="0.012330906"/>
    </inertial>
  </link>
  <joint name="waist1_p_joint" type="revolute">
    <parent link="knee_p_link"/>
    <child link="waist1_p_link"/>
    <origin rpy="0.0 0.0 0.0" xyz="0.0 0.0 0.4"/>
    <axis xyz="0 1 0"/>
    <limit effort="207.0" lower="-2.2689280275926285" upper="2.2689280275926285" velocity="3.14"/>
    <safety_controller k_position="121.0" k_velocity="540.0" soft_lower_limit="-2.2165681500327987" soft_upper_limit="2.2165681500327987"/>
    <dynamics damping="0.003" friction="0.2"/>
  </joint>
  <link name="waist2_y_link">
    <visual name="waist2_y_link_vis">
      <geometry>
        <mesh filename="package://human_description/meshes/M92UW/visual/waist2_y_link.stl" scale="1e-3 1e-3 1e-3"/>
      </geometry>
      <material name="metal">
        <color rgba="0.85 0.85 0.85 1"/>
      </material>
    </visual>
    <collision name="waist2_y_link_col">
      <geometry>
        <mesh filename="package://human_description/meshes/M92UW/collision/waist2_y_link.stl" scale="1e-3 1e-3 1e-3"/>
      </geometry>
    </collision>
    <inertial>
      <origin rpy="0.0 0.0 0.0" xyz="0 0 0.17307869"/>
      <mass value="0.70904416"/>
      <inertia ixx="0.0010443308" ixy="0" ixz="0" iyy="0.0010443307" iyz="0" izz="0.002054833"/>
    </inertial>
  </link>
  <joint name="waist2_y_joint" type="revolute">
    <parent link="waist1_p_link"/>
    <child link="waist2_y_link"/>
    <origin rpy="0.0 0.0 0.0" xyz="0.0 0.0 0.0"/>
    <axis xyz="0 0 1"/>
    <limit effort="207.0" lower="-1.5707963267948966" upper="1.5707963267948966" velocity="3.14"/>
    <safety_controller k_position="121.0" k_velocity="540.0" soft_lower_limit="-1.5184364492350666" soft_upper_limit="1.5184364492350666"/>
    <dynamics damping="0.003" friction="0.2"/>
  </joint>
  <link name="torso_link">
    <visual name="torso_link_vis">
      <geometry>
        <mesh filename="package://human_description/meshes/M92UW/visual/torso_link.stl" scale="1e-3 1e-3 1e-3"/>
      </geometry>
      <material name="metal">
        <color rgba="0.85 0.85 0.85 1"/>
      </material>
    </visual>
    <collision name="torso_link_col">
      <geometry>
        <mesh filename="package://human_description/meshes/M92UW/collision/torso_link.stl" scale="1e-3 1e-3 1e-3"/>
      </geometry>
    </collision>
    <inertial>
      <origin rpy="0.0 0.0 0.0" xyz="-0.0085487881 -9.606895e-06 -0.077759044"/>
      <mass value="12.350557"/>
      <inertia ixx="0.35316138" ixy="-1.0848429e-05" ixz="-0.010659045" iyy="0.26640983" iyz="8.9227842e-06" izz="0.20173237"/>
    </inertial>
  </link>
  <joint name="torso_fixed_joint" type="fixed">
    <parent link="waist2_y_link"/>
    <child link="torso_link"/>
    <origin rpy="0.0 0.0 0.0" xyz="0.0 0.0 0.510000061"/>
    <axis xyz="0 0 1"/>
  </joint>
  <ros2_control name="waist_system" type="system">
    <hardware>
      <plugin>mujoco_ros2_control/MujocoSystem</plugin>
    </hardware>
    <joint name="waist1_p_joint">
      <param name="initial_position">0.0</param>
      <command_interface name="position"/>
      <state_interface name="position">
        <param name="initial_value">0.0</param>
      </state_interface>
      <state_interface name="velocity"/>
      <state_interface name="effort"/>
    </joint>
    <transmission name="waist1_p_transmission">
      <plugin>transmission_interface/SimpleTransmission</plugin>
      <joint name="waist1_p_joint" role="joint1">
        <mechanical_reduction>1.0</mechanical_reduction>
        <offset>0</offset>
      </joint>
      <actuator name="waist1_p_actuator" role="actuator1">
        <mechanical_reduction>1.0</mechanical_reduction>
        <offset>0</offset>
      </actuator>
    </transmission>
    <joint name="waist2_y_joint">
      <param name="initial_position">0.0</param>
      <command_interface name="position"/>
      <state_interface name="position">
        <param name="initial_value">0.0</param>
      </state_interface>
      <state_interface name="velocity"/>
      <state_interface name="effort"/>
    </joint>
    <transmission name="waist2_y_transmission">
      <plugin>transmission_interface/SimpleTransmission</plugin>
      <joint name="waist2_y_joint" role="joint1">
        <mechanical_reduction>1.0</mechanical_reduction>
        <offset>0</offset>
      </joint>
      <actuator name="waist2_y_actuator" role="actuator1">
        <mechanical_reduction>1.0</mechanical_reduction>
        <offset>0</offset>
      </actuator>
    </transmission>
  </ros2_control>
  <link name="head1_y_link">
    <visual name="head1_y_link_vis">
      <origin rpy="0 0 0" xyz="0 0 0"/>
      <geometry>
        <sphere radius="0.005"/>
      </geometry>
      <material name="metal">
        <color rgba="0.85 0.85 0.85 1"/>
      </material>
    </visual>
    <collision name="head1_y_link_col">
      <origin rpy="0 0 0" xyz="0 0 0"/>
      <geometry>
        <sphere radius="0.005"/>
      </geometry>
    </collision>
    <inertial>
      <origin rpy="0. 0. 0." xyz="0. 0. 0."/>
      <mass value="1e-05"/>
      <inertia ixx="8.333333333333334e-11" ixy="0" ixz="0" iyy="8.333333333333334e-11" iyz="0" izz="1.25e-10"/>
    </inertial>
  </link>
  <joint name="head1_y_joint" type="revolute">
    <parent link="torso_link"/>
    <child link="head1_y_link"/>
    <origin rpy="0.0 0.227 0.0" xyz="0.00825076246 0.0 0.187487518331"/>
    <axis xyz="0 0 1"/>
    <limit effort="16.0" lower="-0.7853981633974483" upper="0.7853981633974483" velocity="6.0"/>
    <safety_controller k_position="121.0" k_velocity="540.0" soft_lower_limit="-0.7330382858376184" soft_upper_limit="0.7330382858376184"/>
    <dynamics damping="0.003" friction="0.2"/>
  </joint>
  <link name="head2_p_link">
    <visual name="head2_p_link_vis">
      <geometry>
        <mesh filename="package://human_description/meshes/M92UW/visual/head2_p_link.stl" scale="1 1 1"/>
      </geometry>
      <material name="metal">
        <color rgba="0.85 0.85 0.85 1"/>
      </material>
    </visual>
    <collision name="head2_p_link_col">
      <geometry>
        <mesh filename="package://human_description/meshes/M92UW/collision/head2_p_link.stl" scale="1 1 1"/>
      </geometry>
    </collision>
    <inertial>
      <origin rpy="0.0 0.0 0.0" xyz="0.010024515 0 0.003680398"/>
      <mass value="2.9973416"/>
      <inertia ixx="0.024441669" ixy="0" ixz="-0.0010874083" iyy="0.027526989" iyz="0" izz="0.010800554"/>
    </inertial>
  </link>
  <joint name="head2_p_joint" type="revolute">
    <parent link="head1_y_link"/>
    <child link="head2_p_link"/>
    <origin rpy="0.0 0.0 0.0" xyz="0.0 0.0 0.0"/>
    <axis xyz="0 1 0"/>
    <limit effort="15.0" lower="-0.3490658503988659" upper="0.2617993877991494" velocity="8.0"/>
    <safety_controller k_position="121.0" k_velocity="540.0" soft_lower_limit="-0.29670597283903605" soft_upper_limit="0.20943951023931953"/>
    <dynamics damping="0.003" friction="0.2"/>
  </joint>
  <ros2_control name="head_system" type="system">
    <hardware>
      <plugin>mujoco_ros2_control/MujocoSystem</plugin>
    </hardware>
    <joint name="head1_y_joint">
      <param name="initial_position">0.0</param>
      <command_interface name="position"/>
      <state_interface name="position">
        <param name="initial_value">0.0</param>
      </state_interface>
      <state_interface name="velocity"/>
      <state_interface name="effort"/>
    </joint>
    <transmission name="head1_y_transmission">
      <plugin>transmission_interface/SimpleTransmission</plugin>
      <joint name="head1_y_joint" role="joint1">
        <mechanical_reduction>1.0</mechanical_reduction>
        <offset>0</offset>
      </joint>
      <actuator name="head1_y_actuator" role="actuator1">
        <mechanical_reduction>1.0</mechanical_reduction>
        <offset>0</offset>
      </actuator>
    </transmission>
    <joint name="head2_p_joint">
      <param name="initial_position">0.0</param>
      <command_interface name="position"/>
      <state_interface name="position">
        <param name="initial_value">0.0</param>
      </state_interface>
      <state_interface name="velocity"/>
      <state_interface name="effort"/>
    </joint>
    <transmission name="head2_p_transmission">
      <plugin>transmission_interface/SimpleTransmission</plugin>
      <joint name="head2_p_joint" role="joint1">
        <mechanical_reduction>1.0</mechanical_reduction>
        <offset>0</offset>
      </joint>
      <actuator name="head2_p_actuator" role="actuator1">
        <mechanical_reduction>1.0</mechanical_reduction>
        <offset>0</offset>
      </actuator>
    </transmission>
  </ros2_control>
  <link name="l_arm1_shoulder_p_link">
    <visual name="l_arm1_shoulder_p_link_vis">
      <geometry>
        <mesh filename="package://human_description/meshes/M92UW/visual/l_arm1_shoulder_p_link.stl" scale="1e-3 1e-3 1e-3"/>
      </geometry>
      <material name="metal">
        <color rgba="0.85 0.85 0.85 1"/>
      </material>
    </visual>
    <collision name="l_arm1_shoulder_p_link_col">
      <geometry>
        <mesh filename="package://human_description/meshes/M92UW/collision/l_arm1_shoulder_p_link.stl" scale="1e-3 1e-3 1e-3"/>
      </geometry>
    </collision>
    <inertial>
      <origin rpy="0.0 0.0 0.0" xyz="0.008950692823963513 -0.007910244340673698 0.001047817615140858"/>
      <mass value="2.347873199255413"/>
      <inertia ixx="0.00371805577636075" ixy="-0.00020375534708451775" ixz="3.609106173368525e-05" iyy="0.004459283172641818" iyz="5.624647211110556e-05" izz="0.004925669991342847"/>
    </inertial>
  </link>
  <joint name="l_arm1_shoulder_p_joint" type="revolute">
    <parent link="torso_link"/>
    <child link="l_arm1_shoulder_p_link"/>
    <origin rpy="0.0 0.0 0.0" xyz="0.0 0.225 0.0"/>
    <axis xyz="0 1 0"/>
    <limit effort="107.0" lower="-3.141592653589793" upper="1.0000736613927508" velocity="3.9"/>
    <safety_controller k_position="121.0" k_velocity="540.0" soft_lower_limit="-3.0892327760299634" soft_upper_limit="0.9477137838329208"/>
    <dynamics damping="0.003" friction="0.2"/>
  </joint>
  <link name="l_arm2_shoulder_r_link">
    <visual name="l_arm2_shoulder_r_link_vis">
      <geometry>
        <mesh filename="package://human_description/meshes/M92UW/visual/l_arm2_shoulder_r_link.stl" scale="1e-3 1e-3 1e-3"/>
      </geometry>
      <material name="metal">
        <color rgba="0.85 0.85 0.85 1"/>
      </material>
    </visual>
    <collision name="l_arm2_shoulder_r_link_col">
      <geometry>
        <mesh filename="package://human_description/meshes/M92UW/collision/l_arm2_shoulder_r_link.stl" scale="1e-3 1e-3 1e-3"/>
      </geometry>
    </collision>
    <inertial>
      <origin rpy="0.0 0.0 0.0" xyz="0.00036305191629661246 0.011843042908443239 -0.03652190992211854"/>
      <mass value="0.752587840927864"/>
      <inertia ixx="0.0026036114569122793" ixy="8.592053527867745e-06" ixz="1.6856075010420394e-05" iyy="0.0024594847856526784" iyz="0.0002802648051565737" izz="0.0016631005538151674"/>
    </inertial>
  </link>
  <joint name="l_arm2_shoulder_r_joint" type="revolute">
    <parent link="l_arm1_shoulder_p_link"/>
    <child link="l_arm2_shoulder_r_link"/>
    <origin rpy="0.0 0.0 0.0" xyz="0.0 0.0 0.0"/>
    <axis xyz="1 0 0"/>
    <limit effort="107.0" lower="-0.5235987755982988" upper="1.5707963267948966" velocity="3.9"/>
    <safety_controller k_position="121.0" k_velocity="540.0" soft_lower_limit="-0.47123889803846897" soft_upper_limit="1.5184364492350666"/>
    <dynamics damping="0.003" friction="0.2"/>
  </joint>
  <link name="l_arm3_shoulder_y_link">
    <visual name="l_arm3_shoulder_y_link_vis">
      <geometry>
        <mesh filename="package://human_description/meshes/M92UW/visual/l_arm3_shoulder_y_link.stl" scale="1e-3 1e-3 1e-3"/>
      </geometry>
      <material name="metal">
        <color rgba="0.85 0.85 0.85 1"/>
      </material>
    </visual>
    <collision name="l_arm3_shoulder_y_link_col">
      <geometry>
        <mesh filename="package://human_description/meshes/M92UW/collision/l_arm3_shoulder_y_link.stl" scale="1e-3 1e-3 1e-3"/>
      </geometry>
    </collision>
    <inertial>
      <origin rpy="0.0 0.0 0.0" xyz="0.009483721082429376 0.0009283823410288751 0.07220283077817466"/>
      <mass value="2.8032226973946757"/>
      <inertia ixx="0.01709273409680172" ixy="-3.1041493444281146e-05" ixz="0.0018537887840343332" iyy="0.017612642148909542" iyz="0.00017830759281331393" izz="0.003132408910489035"/>
    </inertial>
  </link>
  <joint name="l_arm3_shoulder_y_joint" type="revolute">
    <parent link="l_arm2_shoulder_r_link"/>
    <child link="l_arm3_shoulder_y_link"/>
    <origin rpy="0.0 0.0 0.0" xyz="0.0 0.0275 -0.28"/>
    <axis xyz="0 0 1"/>
    <limit effort="70.0" lower="-3.139847324337799" upper="3.139847324337799" velocity="3.8"/>
    <safety_controller k_position="121.0" k_velocity="540.0" soft_lower_limit="-3.087487446777969" soft_upper_limit="3.087487446777969"/>
    <dynamics damping="0.003" friction="0.2"/>
  </joint>
  <link name="l_arm4_elbow_p_link">
    <visual name="l_arm4_elbow_p_link_vis">
      <geometry>
        <mesh filename="package://human_description/meshes/M92UW/visual/l_arm4_elbow_p_link.stl" scale="1e-3 1e-3 1e-3"/>
      </geometry>
      <material name="metal">
        <color rgba="0.85 0.85 0.85 1"/>
      </material>
    </visual>
    <collision name="l_arm4_elbow_p_link_col">
      <geometry>
        <mesh filename="package://human_description/meshes/M92UW/collision/l_arm4_elbow_p_link.stl" scale="1e-3 1e-3 1e-3"/>
      </geometry>
    </collision>
    <inertial>
      <origin rpy="0.0 0.0 0.0" xyz="-0.016878859016134812 -0.002424599482891291 -0.08347296858171128"/>
      <mass value="1.4951436605879314"/>
      <inertia ixx="0.004293550118219109" ixy="4.3192250569185595e-05" ixz="-0.0003401699176851234" iyy="0.004009022454595748" iyz="0.00022976670691615358" izz="0.0019433761729977456"/>
    </inertial>
  </link>
  <joint name="l_arm4_elbow_p_joint" type="revolute">
    <parent link="l_arm3_shoulder_y_link"/>
    <child link="l_arm4_elbow_p_link"/>
    <origin rpy="0.0 0.0 0.0" xyz="0.02 0.0 0.0"/>
    <axis xyz="0 1 0"/>
    <limit effort="70.0" lower="-2.6162485487394997" upper="0.05235987755982988" velocity="3.8"/>
    <safety_controller k_position="121.0" k_velocity="540.0" soft_lower_limit="-2.5638886711796705" soft_upper_limit="0.0"/>
    <dynamics damping="0.003" friction="0.2"/>
  </joint>
  <link name="l_arm5_wrist_y_link">
    <visual name="l_arm5_wrist_y_link_vis">
      <geometry>
        <mesh filename="package://human_description/meshes/M92UW/visual/l_arm5_wrist_y_link.stl" scale="1e-3 1e-3 1e-3"/>
      </geometry>
      <material name="metal">
        <color rgba="0.85 0.85 0.85 1"/>
      </material>
    </visual>
    <collision name="l_arm5_wrist_y_link_col">
      <geometry>
        <mesh filename="package://human_description/meshes/M92UW/collision/l_arm5_wrist_y_link.stl" scale="1e-3 1e-3 1e-3"/>
      </geometry>
    </collision>
    <inertial>
      <origin rpy="0.0 0.0 0.0" xyz="1.0105403425632446e-05 -0.0007920766777345156 0.033467755020747975"/>
      <mass value="0.27226645693469925"/>
      <inertia ixx="0.00042677981237483024" ixy="1.5635914930696041e-07" ixz="-8.511440415016232e-08" iyy="0.00029281147887157377" iyz="-2.9845719981923703e-05" izz="0.0003716353641820523"/>
    </inertial>
  </link>
  <joint name="l_arm5_wrist_y_joint" type="revolute">
    <parent link="l_arm4_elbow_p_link"/>
    <child link="l_arm5_wrist_y_link"/>
    <origin rpy="0.0 0.0 0.0" xyz="-0.02 0.0 -0.213"/>
    <axis xyz="0 0 1"/>
    <limit effort="36.0" lower="-3.141592653589793" upper="3.141592653589793" velocity="4.3"/>
    <safety_controller k_position="121.0" k_velocity="540.0" soft_lower_limit="-3.0892327760299634" soft_upper_limit="3.0892327760299634"/>
    <dynamics damping="0.003" friction="0.2"/>
  </joint>
  <link name="l_arm6_wrist_p_link">
    <visual name="l_arm6_wrist_p_link_vis">
      <geometry>
        <mesh filename="package://human_description/meshes/M92UW/visual/l_arm6_wrist_p_link.stl" scale="1e-3 1e-3 1e-3"/>
      </geometry>
      <material name="metal">
        <color rgba="0.85 0.85 0.85 1"/>
      </material>
    </visual>
    <collision name="l_arm6_wrist_p_link_col">
      <geometry>
        <mesh filename="package://human_description/meshes/M92UW/collision/l_arm6_wrist_p_link.stl" scale="1e-3 1e-3 1e-3"/>
      </geometry>
    </collision>
    <inertial>
      <origin rpy="0.0 0.0 0.0" xyz="-0.0023977486620611805 0.0032941533904827926 -0.02747107099422101"/>
      <mass value="0.8769025437478114"/>
      <inertia ixx="0.0011344037552627772" ixy="-5.74262388435353e-06" ixz="-5.7053004228770495e-05" iyy="0.0011212906698454524" iyz="-8.099881421779838e-05" izz="0.0005394058553208015"/>
    </inertial>
  </link>
  <joint name="l_arm6_wrist_p_joint" type="revolute">
    <parent link="l_arm5_wrist_y_link"/>
    <child link="l_arm6_wrist_p_link"/>
    <origin rpy="0.0 0.0 0.0" xyz="0.0 0.0 0.0"/>
    <axis xyz="0 1 0"/>
    <limit effort="15.0" lower="-1.3962634015954636" upper="1.3962634015954636" velocity="7.7"/>
    <safety_controller k_position="121.0" k_velocity="540.0" soft_lower_limit="-1.3439035240356338" soft_upper_limit="1.3439035240356338"/>
    <dynamics damping="0.003" friction="0.2"/>
  </joint>
  <link name="l_arm7_wrist_r_link">
    <visual name="l_arm7_wrist_r_link_vis">
      <geometry>
        <mesh filename="package://human_description/meshes/M92UW/visual/l_arm7_wrist_r_link.stl" scale="1e-3 1e-3 1e-3"/>
      </geometry>
      <material name="metal">
        <color rgba="0.85 0.85 0.85 1"/>
      </material>
    </visual>
    <collision name="l_arm7_wrist_r_link_col">
      <geometry>
        <mesh filename="package://human_description/meshes/M92UW/collision/l_arm7_wrist_r_link.stl" scale="1e-3 1e-3 1e-3"/>
      </geometry>
    </collision>
    <inertial>
      <origin rpy="0.0 0.0 0.0" xyz="0.005628948451189553 -0.0002631286864539303 -0.13713379318786653"/>
      <mass value="1.1182834022922525"/>
      <inertia ixx="0.00054013059" ixy="-3.4201381e-06" ixz="1.2981479e-05" iyy="0.00040641427" iyz="-1.619246e-05" izz="0.0002867356"/>
    </inertial>
  </link>
  <joint name="l_arm7_wrist_r_joint" type="revolute">
    <parent link="l_arm6_wrist_p_link"/>
    <child link="l_arm7_wrist_r_link"/>
    <origin rpy="0.0 0.0 0.0" xyz="0.0 0.0 -0.055"/>
    <axis xyz="1 0 0"/>
    <limit effort="15.0" lower="-1.3962634015954636" upper="1.3962634015954636" velocity="7.7"/>
    <safety_controller k_position="121.0" k_velocity="540.0" soft_lower_limit="-1.3439035240356338" soft_upper_limit="1.3439035240356338"/>
    <dynamics damping="0.003" friction="0.2"/>
  </joint>
  <link name="l_end_effector_link">
    <inertial>
      <origin rpy="0. 0. 0." xyz="0. 0. 0."/>
      <mass value="1e-05"/>
      <inertia ixx="3.333333333333333e-12" ixy="0" ixz="0" iyy="3.333333333333333e-12" iyz="0" izz="5.0000000000000005e-12"/>
    </inertial>
  </link>
  <joint name="l_end_effector_fixed_joint" type="fixed">
    <parent link="l_arm7_wrist_r_link"/>
    <child link="l_end_effector_link"/>
    <origin rpy="0 0 0" xyz="0 0 0"/>
    <axis xyz="0 0 1"/>
  </joint>
  <ros2_control name="l_arm_system" type="system">
    <hardware>
      <plugin>mujoco_ros2_control/MujocoSystem</plugin>
    </hardware>
    <joint name="l_arm1_shoulder_p_joint">
      <param name="initial_position">0.0</param>
      <command_interface name="position"/>
      <state_interface name="position">
        <param name="initial_value">0.0</param>
      </state_interface>
      <state_interface name="velocity"/>
      <state_interface name="effort"/>
    </joint>
    <transmission name="l_arm1_shoulder_p_transmission">
      <plugin>transmission_interface/SimpleTransmission</plugin>
      <joint name="l_arm1_shoulder_p_joint" role="joint1">
        <mechanical_reduction>1.0</mechanical_reduction>
        <offset>0</offset>
      </joint>
      <actuator name="l_arm1_shoulder_p_actuator" role="actuator1">
        <mechanical_reduction>1.0</mechanical_reduction>
        <offset>0</offset>
      </actuator>
    </transmission>
    <joint name="l_arm2_shoulder_r_joint">
      <param name="initial_position">0.0</param>
      <command_interface name="position"/>
      <state_interface name="position">
        <param name="initial_value">0.0</param>
      </state_interface>
      <state_interface name="velocity"/>
      <state_interface name="effort"/>
    </joint>
    <transmission name="l_arm2_shoulder_r_transmission">
      <plugin>transmission_interface/SimpleTransmission</plugin>
      <joint name="l_arm2_shoulder_r_joint" role="joint1">
        <mechanical_reduction>1.0</mechanical_reduction>
        <offset>0</offset>
      </joint>
      <actuator name="l_arm2_shoulder_r_actuator" role="actuator1">
        <mechanical_reduction>1.0</mechanical_reduction>
        <offset>0</offset>
      </actuator>
    </transmission>
    <joint name="l_arm3_shoulder_y_joint">
      <param name="initial_position">0.0</param>
      <command_interface name="position"/>
      <state_interface name="position">
        <param name="initial_value">0.0</param>
      </state_interface>
      <state_interface name="velocity"/>
      <state_interface name="effort"/>
    </joint>
    <transmission name="l_arm3_shoulder_y_transmission">
      <plugin>transmission_interface/SimpleTransmission</plugin>
      <joint name="l_arm3_shoulder_y_joint" role="joint1">
        <mechanical_reduction>1.0</mechanical_reduction>
        <offset>0</offset>
      </joint>
      <actuator name="l_arm3_shoulder_y_actuator" role="actuator1">
        <mechanical_reduction>1.0</mechanical_reduction>
        <offset>0</offset>
      </actuator>
    </transmission>
    <joint name="l_arm4_elbow_p_joint">
      <param name="initial_position">0.0</param>
      <command_interface name="position"/>
      <state_interface name="position">
        <param name="initial_value">0.0</param>
      </state_interface>
      <state_interface name="velocity"/>
      <state_interface name="effort"/>
    </joint>
    <transmission name="l_arm4_elbow_p_transmission">
      <plugin>transmission_interface/SimpleTransmission</plugin>
      <joint name="l_arm4_elbow_p_joint" role="joint1">
        <mechanical_reduction>1.0</mechanical_reduction>
        <offset>0</offset>
      </joint>
      <actuator name="l_arm4_elbow_p_actuator" role="actuator1">
        <mechanical_reduction>1.0</mechanical_reduction>
        <offset>0</offset>
      </actuator>
    </transmission>
    <joint name="l_arm5_wrist_y_joint">
      <param name="initial_position">0.0</param>
      <command_interface name="position"/>
      <state_interface name="position">
        <param name="initial_value">0.0</param>
      </state_interface>
      <state_interface name="velocity"/>
      <state_interface name="effort"/>
    </joint>
    <transmission name="l_arm5_wrist_y_transmission">
      <plugin>transmission_interface/SimpleTransmission</plugin>
      <joint name="l_arm5_wrist_y_joint" role="joint1">
        <mechanical_reduction>1.0</mechanical_reduction>
        <offset>0</offset>
      </joint>
      <actuator name="l_arm5_wrist_y_actuator" role="actuator1">
        <mechanical_reduction>1.0</mechanical_reduction>
        <offset>0</offset>
      </actuator>
    </transmission>
    <joint name="l_arm6_wrist_p_joint">
      <param name="initial_position">0.0</param>
      <command_interface name="position"/>
      <state_interface name="position">
        <param name="initial_value">0.0</param>
      </state_interface>
      <state_interface name="velocity"/>
      <state_interface name="effort"/>
    </joint>
    <transmission name="l_arm6_wrist_p_transmission">
      <plugin>transmission_interface/SimpleTransmission</plugin>
      <joint name="l_arm6_wrist_p_joint" role="joint1">
        <mechanical_reduction>1.0</mechanical_reduction>
        <offset>0</offset>
      </joint>
      <actuator name="l_arm6_wrist_p_actuator" role="actuator1">
        <mechanical_reduction>1.0</mechanical_reduction>
        <offset>0</offset>
      </actuator>
    </transmission>
    <joint name="l_arm7_wrist_r_joint">
      <param name="initial_position">0.0</param>
      <command_interface name="position"/>
      <state_interface name="position">
        <param name="initial_value">0.0</param>
      </state_interface>
      <state_interface name="velocity"/>
      <state_interface name="effort"/>
    </joint>
    <transmission name="l_arm7_wrist_r_transmission">
      <plugin>transmission_interface/SimpleTransmission</plugin>
      <joint name="l_arm7_wrist_r_joint" role="joint1">
        <mechanical_reduction>1.0</mechanical_reduction>
        <offset>0</offset>
      </joint>
      <actuator name="l_arm7_wrist_r_actuator" role="actuator1">
        <mechanical_reduction>1.0</mechanical_reduction>
        <offset>0</offset>
      </actuator>
    </transmission>
  </ros2_control>
  <link name="r_arm1_shoulder_p_link">
    <visual name="r_arm1_shoulder_p_link_vis">
      <geometry>
        <mesh filename="package://human_description/meshes/M92UW/visual/r_arm1_shoulder_p_link.stl" scale="1e-3 1e-3 1e-3"/>
      </geometry>
      <material name="metal">
        <color rgba="0.85 0.85 0.85 1"/>
      </material>
    </visual>
    <collision name="r_arm1_shoulder_p_link_col">
      <geometry>
        <mesh filename="package://human_description/meshes/M92UW/collision/r_arm1_shoulder_p_link.stl" scale="1e-3 1e-3 1e-3"/>
      </geometry>
    </collision>
    <inertial>
      <origin rpy="0.0 0.0 0.0" xyz="0.008950692823963513 0.007910244340673698 0.001047817615140858"/>
      <mass value="2.347873199255413"/>
      <inertia ixx="0.00371805577636075" ixy="0.00020375534708451775" ixz="3.609106173368525e-05" iyy="0.004459283172641818" iyz="-5.624647211110556e-05" izz="0.004925669991342847"/>
    </inertial>
  </link>
  <joint name="r_arm1_shoulder_p_joint" type="revolute">
    <parent link="torso_link"/>
    <child link="r_arm1_shoulder_p_link"/>
    <origin rpy="0.0 0.0 0.0" xyz="0.0 -0.225 0.0"/>
    <axis xyz="0 1 0"/>
    <limit effort="107.0" lower="-3.141592653589793" upper="1.0000736613927508" velocity="3.9"/>
    <safety_controller k_position="121.0" k_velocity="540.0" soft_lower_limit="-3.0892327760299634" soft_upper_limit="0.9477137838329208"/>
    <dynamics damping="0.003" friction="0.2"/>
  </joint>
  <link name="r_arm2_shoulder_r_link">
    <visual name="r_arm2_shoulder_r_link_vis">
      <geometry>
        <mesh filename="package://human_description/meshes/M92UW/visual/r_arm2_shoulder_r_link.stl" scale="1e-3 1e-3 1e-3"/>
      </geometry>
      <material name="metal">
        <color rgba="0.85 0.85 0.85 1"/>
      </material>
    </visual>
    <collision name="r_arm2_shoulder_r_link_col">
      <geometry>
        <mesh filename="package://human_description/meshes/M92UW/collision/r_arm2_shoulder_r_link.stl" scale="1e-3 1e-3 1e-3"/>
      </geometry>
    </collision>
    <inertial>
      <origin rpy="0.0 0.0 0.0" xyz="0.00036305191629661246 -0.011843042908443239 -0.03652190992211854"/>
      <mass value="0.752587840927864"/>
      <inertia ixx="0.0026036114569122793" ixy="-8.592053527867745e-06" ixz="1.6856075010420394e-05" iyy="0.0024594847856526784" iyz="-0.0002802648051565737" izz="0.0016631005538151674"/>
    </inertial>
  </link>
  <joint name="r_arm2_shoulder_r_joint" type="revolute">
    <parent link="r_arm1_shoulder_p_link"/>
    <child link="r_arm2_shoulder_r_link"/>
    <origin rpy="0.0 0.0 0.0" xyz="0.0 0.0 0.0"/>
    <axis xyz="1 0 0"/>
    <limit effort="107.0" lower="-1.5707963267948966" upper="0.5235987755982988" velocity="3.9"/>
    <safety_controller k_position="121.0" k_velocity="540.0" soft_lower_limit="-1.5184364492350666" soft_upper_limit="0.47123889803846897"/>
    <dynamics damping="0.003" friction="0.2"/>
  </joint>
  <link name="r_arm3_shoulder_y_link">
    <visual name="r_arm3_shoulder_y_link_vis">
      <geometry>
        <mesh filename="package://human_description/meshes/M92UW/visual/r_arm3_shoulder_y_link.stl" scale="1e-3 1e-3 1e-3"/>
      </geometry>
      <material name="metal">
        <color rgba="0.85 0.85 0.85 1"/>
      </material>
    </visual>
    <collision name="r_arm3_shoulder_y_link_col">
      <geometry>
        <mesh filename="package://human_description/meshes/M92UW/collision/r_arm3_shoulder_y_link.stl" scale="1e-3 1e-3 1e-3"/>
      </geometry>
    </collision>
    <inertial>
      <origin rpy="0.0 0.0 0.0" xyz="0.009483721082429376 -0.0009283823410288751 0.07220283077817466"/>
      <mass value="2.8032226973946757"/>
      <inertia ixx="0.01709273409680172" ixy="3.1041493444281146e-05" ixz="0.0018537887840343332" iyy="0.017612642148909542" iyz="-0.00017830759281331393" izz="0.003132408910489035"/>
    </inertial>
  </link>
  <joint name="r_arm3_shoulder_y_joint" type="revolute">
    <parent link="r_arm2_shoulder_r_link"/>
    <child link="r_arm3_shoulder_y_link"/>
    <origin rpy="0.0 0.0 0.0" xyz="0.0 -0.0275 -0.28"/>
    <axis xyz="0 0 1"/>
    <limit effort="70.0" lower="-3.139847324337799" upper="3.139847324337799" velocity="3.8"/>
    <safety_controller k_position="121.0" k_velocity="540.0" soft_lower_limit="-3.087487446777969" soft_upper_limit="3.087487446777969"/>
    <dynamics damping="0.003" friction="0.2"/>
  </joint>
  <link name="r_arm4_elbow_p_link">
    <visual name="r_arm4_elbow_p_link_vis">
      <geometry>
        <mesh filename="package://human_description/meshes/M92UW/visual/r_arm4_elbow_p_link.stl" scale="1e-3 1e-3 1e-3"/>
      </geometry>
      <material name="metal">
        <color rgba="0.85 0.85 0.85 1"/>
      </material>
    </visual>
    <collision name="r_arm4_elbow_p_link_col">
      <geometry>
        <mesh filename="package://human_description/meshes/M92UW/collision/r_arm4_elbow_p_link.stl" scale="1e-3 1e-3 1e-3"/>
      </geometry>
    </collision>
    <inertial>
      <origin rpy="0.0 0.0 0.0" xyz="-0.016878859016134812 0.002424599482891291 -0.08347296858171128"/>
      <mass value="1.4951436605879314"/>
      <inertia ixx="0.004293550118219109" ixy="-4.3192250569185595e-05" ixz="-0.0003401699176851234" iyy="0.004009022454595748" iyz="-0.00022976670691615358" izz="0.0019433761729977456"/>
    </inertial>
  </link>
  <joint name="r_arm4_elbow_p_joint" type="revolute">
    <parent link="r_arm3_shoulder_y_link"/>
    <child link="r_arm4_elbow_p_link"/>
    <origin rpy="0.0 0.0 0.0" xyz="0.02 0.0 0.0"/>
    <axis xyz="0 1 0"/>
    <limit effort="70.0" lower="-2.6162485487394997" upper="0.05235987755982988" velocity="3.8"/>
    <safety_controller k_position="121.0" k_velocity="540.0" soft_lower_limit="-2.5638886711796705" soft_upper_limit="0.0"/>
    <dynamics damping="0.003" friction="0.2"/>
  </joint>
  <link name="r_arm5_wrist_y_link">
    <visual name="r_arm5_wrist_y_link_vis">
      <geometry>
        <mesh filename="package://human_description/meshes/M92UW/visual/r_arm5_wrist_y_link.stl" scale="1e-3 1e-3 1e-3"/>
      </geometry>
      <material name="metal">
        <color rgba="0.85 0.85 0.85 1"/>
      </material>
    </visual>
    <collision name="r_arm5_wrist_y_link_col">
      <geometry>
        <mesh filename="package://human_description/meshes/M92UW/collision/r_arm5_wrist_y_link.stl" scale="1e-3 1e-3 1e-3"/>
      </geometry>
    </collision>
    <inertial>
      <origin rpy="0.0 0.0 0.0" xyz="1.0105403425632446e-05 0.0007920766777345156 0.033467755020747975"/>
      <mass value="0.27226645693469925"/>
      <inertia ixx="0.00042677981237483024" ixy="-1.5635914930696041e-07" ixz="-8.511440415016232e-08" iyy="0.00029281147887157377" iyz="2.9845719981923703e-05" izz="0.0003716353641820523"/>
    </inertial>
  </link>
  <joint name="r_arm5_wrist_y_joint" type="revolute">
    <parent link="r_arm4_elbow_p_link"/>
    <child link="r_arm5_wrist_y_link"/>
    <origin rpy="0.0 0.0 0.0" xyz="-0.02 0.0 -0.213"/>
    <axis xyz="0 0 1"/>
    <limit effort="36.0" lower="-3.141592653589793" upper="3.141592653589793" velocity="4.3"/>
    <safety_controller k_position="121.0" k_velocity="540.0" soft_lower_limit="-3.0892327760299634" soft_upper_limit="3.0892327760299634"/>
    <dynamics damping="0.003" friction="0.2"/>
  </joint>
  <link name="r_arm6_wrist_p_link">
    <visual name="r_arm6_wrist_p_link_vis">
      <geometry>
        <mesh filename="package://human_description/meshes/M92UW/visual/r_arm6_wrist_p_link.stl" scale="1e-3 1e-3 1e-3"/>
      </geometry>
      <material name="metal">
        <color rgba="0.85 0.85 0.85 1"/>
      </material>
    </visual>
    <collision name="r_arm6_wrist_p_link_col">
      <geometry>
        <mesh filename="package://human_description/meshes/M92UW/collision/r_arm6_wrist_p_link.stl" scale="1e-3 1e-3 1e-3"/>
      </geometry>
    </collision>
    <inertial>
      <origin rpy="0.0 0.0 0.0" xyz="-0.0023977486620611805 -0.0032941533904827926 -0.02747107099422101"/>
      <mass value="0.8769025437478114"/>
      <inertia ixx="0.0011344037552627772" ixy="5.74262388435353e-06" ixz="-5.7053004228770495e-05" iyy="0.0011212906698454524" iyz="8.099881421779838e-05" izz="0.0005394058553208015"/>
    </inertial>
  </link>
  <joint name="r_arm6_wrist_p_joint" type="revolute">
    <parent link="r_arm5_wrist_y_link"/>
    <child link="r_arm6_wrist_p_link"/>
    <origin rpy="0.0 0.0 0.0" xyz="0.0 0.0 0.0"/>
    <axis xyz="0 1 0"/>
    <limit effort="15.0" lower="-1.3962634015954636" upper="1.3962634015954636" velocity="7.7"/>
    <safety_controller k_position="121.0" k_velocity="540.0" soft_lower_limit="-1.3439035240356338" soft_upper_limit="1.3439035240356338"/>
    <dynamics damping="0.003" friction="0.2"/>
  </joint>
  <link name="r_arm7_wrist_r_link">
    <visual name="r_arm7_wrist_r_link_vis">
      <geometry>
        <mesh filename="package://human_description/meshes/M92UW/visual/r_arm7_wrist_r_link.stl" scale="1e-3 1e-3 1e-3"/>
      </geometry>
      <material name="metal">
        <color rgba="0.85 0.85 0.85 1"/>
      </material>
    </visual>
    <collision name="r_arm7_wrist_r_link_col">
      <geometry>
        <mesh filename="package://human_description/meshes/M92UW/collision/r_arm7_wrist_r_link.stl" scale="1e-3 1e-3 1e-3"/>
      </geometry>
    </collision>
    <inertial>
      <origin rpy="0.0 0.0 0.0" xyz="0.005628948451189553 0.0002631286864539303 -0.13713379318786653"/>
      <mass value="1.1182834022922525"/>
      <inertia ixx="0.00054013059" ixy="3.4201381e-06" ixz="1.2981479e-05" iyy="0.00040641427" iyz="1.619246e-05" izz="0.0002867356"/>
    </inertial>
  </link>
  <joint name="r_arm7_wrist_r_joint" type="revolute">
    <parent link="r_arm6_wrist_p_link"/>
    <child link="r_arm7_wrist_r_link"/>
    <origin rpy="0.0 0.0 0.0" xyz="0.0 0.0 -0.055"/>
    <axis xyz="1 0 0"/>
    <limit effort="15.0" lower="-1.3962634015954636" upper="1.3962634015954636" velocity="7.7"/>
    <safety_controller k_position="121.0" k_velocity="540.0" soft_lower_limit="-1.3439035240356338" soft_upper_limit="1.3439035240356338"/>
    <dynamics damping="0.003" friction="0.2"/>
  </joint>
  <link name="r_end_effector_link">
    <inertial>
      <origin rpy="0. 0. 0." xyz="0. 0. 0."/>
      <mass value="1e-05"/>
      <inertia ixx="3.333333333333333e-12" ixy="0" ixz="0" iyy="3.333333333333333e-12" iyz="0" izz="5.0000000000000005e-12"/>
    </inertial>
  </link>
  <joint name="r_end_effector_fixed_joint" type="fixed">
    <parent link="r_arm7_wrist_r_link"/>
    <child link="r_end_effector_link"/>
    <origin rpy="0 0 0" xyz="0 0 0"/>
    <axis xyz="0 0 1"/>
  </joint>
  <ros2_control name="r_arm_system" type="system">
    <hardware>
      <plugin>mujoco_ros2_control/MujocoSystem</plugin>
    </hardware>
    <joint name="r_arm1_shoulder_p_joint">
      <param name="initial_position">0.0</param>
      <command_interface name="position"/>
      <state_interface name="position">
        <param name="initial_value">0.0</param>
      </state_interface>
      <state_interface name="velocity"/>
      <state_interface name="effort"/>
    </joint>
    <transmission name="r_arm1_shoulder_p_transmission">
      <plugin>transmission_interface/SimpleTransmission</plugin>
      <joint name="r_arm1_shoulder_p_joint" role="joint1">
        <mechanical_reduction>1.0</mechanical_reduction>
        <offset>0</offset>
      </joint>
      <actuator name="r_arm1_shoulder_p_actuator" role="actuator1">
        <mechanical_reduction>1.0</mechanical_reduction>
        <offset>0</offset>
      </actuator>
    </transmission>
    <joint name="r_arm2_shoulder_r_joint">
      <param name="initial_position">0.0</param>
      <command_interface name="position"/>
      <state_interface name="position">
        <param name="initial_value">0.0</param>
      </state_interface>
      <state_interface name="velocity"/>
      <state_interface name="effort"/>
    </joint>
    <transmission name="r_arm2_shoulder_r_transmission">
      <plugin>transmission_interface/SimpleTransmission</plugin>
      <joint name="r_arm2_shoulder_r_joint" role="joint1">
        <mechanical_reduction>1.0</mechanical_reduction>
        <offset>0</offset>
      </joint>
      <actuator name="r_arm2_shoulder_r_actuator" role="actuator1">
        <mechanical_reduction>1.0</mechanical_reduction>
        <offset>0</offset>
      </actuator>
    </transmission>
    <joint name="r_arm3_shoulder_y_joint">
      <param name="initial_position">0.0</param>
      <command_interface name="position"/>
      <state_interface name="position">
        <param name="initial_value">0.0</param>
      </state_interface>
      <state_interface name="velocity"/>
      <state_interface name="effort"/>
    </joint>
    <transmission name="r_arm3_shoulder_y_transmission">
      <plugin>transmission_interface/SimpleTransmission</plugin>
      <joint name="r_arm3_shoulder_y_joint" role="joint1">
        <mechanical_reduction>1.0</mechanical_reduction>
        <offset>0</offset>
      </joint>
      <actuator name="r_arm3_shoulder_y_actuator" role="actuator1">
        <mechanical_reduction>1.0</mechanical_reduction>
        <offset>0</offset>
      </actuator>
    </transmission>
    <joint name="r_arm4_elbow_p_joint">
      <param name="initial_position">0.0</param>
      <command_interface name="position"/>
      <state_interface name="position">
        <param name="initial_value">0.0</param>
      </state_interface>
      <state_interface name="velocity"/>
      <state_interface name="effort"/>
    </joint>
    <transmission name="r_arm4_elbow_p_transmission">
      <plugin>transmission_interface/SimpleTransmission</plugin>
      <joint name="r_arm4_elbow_p_joint" role="joint1">
        <mechanical_reduction>1.0</mechanical_reduction>
        <offset>0</offset>
      </joint>
      <actuator name="r_arm4_elbow_p_actuator" role="actuator1">
        <mechanical_reduction>1.0</mechanical_reduction>
        <offset>0</offset>
      </actuator>
    </transmission>
    <joint name="r_arm5_wrist_y_joint">
      <param name="initial_position">0.0</param>
      <command_interface name="position"/>
      <state_interface name="position">
        <param name="initial_value">0.0</param>
      </state_interface>
      <state_interface name="velocity"/>
      <state_interface name="effort"/>
    </joint>
    <transmission name="r_arm5_wrist_y_transmission">
      <plugin>transmission_interface/SimpleTransmission</plugin>
      <joint name="r_arm5_wrist_y_joint" role="joint1">
        <mechanical_reduction>1.0</mechanical_reduction>
        <offset>0</offset>
      </joint>
      <actuator name="r_arm5_wrist_y_actuator" role="actuator1">
        <mechanical_reduction>1.0</mechanical_reduction>
        <offset>0</offset>
      </actuator>
    </transmission>
    <joint name="r_arm6_wrist_p_joint">
      <param name="initial_position">0.0</param>
      <command_interface name="position"/>
      <state_interface name="position">
        <param name="initial_value">0.0</param>
      </state_interface>
      <state_interface name="velocity"/>
      <state_interface name="effort"/>
    </joint>
    <transmission name="r_arm6_wrist_p_transmission">
      <plugin>transmission_interface/SimpleTransmission</plugin>
      <joint name="r_arm6_wrist_p_joint" role="joint1">
        <mechanical_reduction>1.0</mechanical_reduction>
        <offset>0</offset>
      </joint>
      <actuator name="r_arm6_wrist_p_actuator" role="actuator1">
        <mechanical_reduction>1.0</mechanical_reduction>
        <offset>0</offset>
      </actuator>
    </transmission>
    <joint name="r_arm7_wrist_r_joint">
      <param name="initial_position">0.0</param>
      <command_interface name="position"/>
      <state_interface name="position">
        <param name="initial_value">0.0</param>
      </state_interface>
      <state_interface name="velocity"/>
      <state_interface name="effort"/>
    </joint>
    <transmission name="r_arm7_wrist_r_transmission">
      <plugin>transmission_interface/SimpleTransmission</plugin>
      <joint name="r_arm7_wrist_r_joint" role="joint1">
        <mechanical_reduction>1.0</mechanical_reduction>
        <offset>0</offset>
      </joint>
      <actuator name="r_arm7_wrist_r_actuator" role="actuator1">
        <mechanical_reduction>1.0</mechanical_reduction>
        <offset>0</offset>
      </actuator>
    </transmission>
  </ros2_control>
  <link name="l_hand_palm_link">
    <visual name="l_hand_palm_link_vis">
      <origin rpy="0 0 0" xyz="0 0 0"/>
      <geometry>
        <sphere radius="0.005"/>
      </geometry>
      <material name="yellow">
        <color rgba="0.9 1.0 0.0 1.0"/>
      </material>
    </visual>
    <collision name="l_hand_palm_link_col">
      <origin rpy="0 0 0" xyz="0 0 0"/>
      <geometry>
        <sphere radius="0.005"/>
      </geometry>
    </collision>
    <inertial>
      <origin rpy="0. 0. 0." xyz="0. 0. 0."/>
      <mass value="1e-05"/>
      <inertia ixx="8.333333333333334e-11" ixy="0" ixz="0" iyy="8.333333333333334e-11" iyz="0" izz="1.25e-10"/>
    </inertial>
  </link>
  <joint name="l_hand_palm_fixed_joint" type="fixed">
    <parent link="l_end_effector_link"/>
    <child link="l_hand_palm_link"/>
    <origin rpy="3.1415926 0.0 1.5707963" xyz="-2.2e-11 2.45e-10 -0.1002"/>
    <axis xyz="0 0 1"/>
  </joint>
  <link name="l_thumb_cmc_y_link">
    <visual name="l_thumb_cmc_y_link_vis">
      <origin rpy="0 0 0" xyz="0 0 0"/>
      <geometry>
        <mesh filename="package://human_description/meshes/robot_hands/m92u_hand/visual/l_thumb_cmc_y_link.stl" scale="1e-3 1e-3 1e-3"/>
      </geometry>
      <material name="metal">
        <color rgba="0.85 0.85 0.85 1"/>
      </material>
    </visual>
    <collision name="l_thumb_cmc_y_link_col">
      <origin rpy="0 0 0" xyz="0 0 0"/>
      <geometry>
        <mesh filename="package://human_description/meshes/robot_hands/m92u_hand/collision/l_thumb_cmc_y_link.stl" scale="1e-3 1e-3 1e-3"/>
      </geometry>
    </collision>
    <inertial>
      <origin rpy="0.0 0.0 0.0" xyz="-0.0043445795 0.00073516028 0.00092114437"/>
      <mass value="0.0001"/>
      <inertia ixx="1.2807232e-07" ixy="-2.6031726e-08" ixz="9.2990531e-09" iyy="2.0994928e-07" iyz="2.3599758e-09" izz="1.8089779e-07"/>
    </inertial>
  </link>
  <joint name="l_thumb_cmc_y_joint" type="revolute">
    <parent link="l_hand_palm_link"/>
    <child link="l_thumb_cmc_y_link"/>
    <origin rpy="6.98131688888889e-09 4.188790133333333e-08 0.17452838436624443" xyz="-0.01285999 0.030499 0.0422"/>
    <axis xyz="0 0 1"/>
    <limit effort="5.0" lower="0.0" upper="1.5707963267948966" velocity="1.0"/>
    <dynamics damping="0.05" friction="0.2"/>
  </joint>
  <link name="l_thumb_cmc_p_link">
    <visual name="l_thumb_cmc_p_link_vis">
      <origin rpy="0 0 0" xyz="0 0 0"/>
      <geometry>
        <mesh filename="package://human_description/meshes/robot_hands/m92u_hand/visual/l_thumb_cmc_p_link.stl" scale="1e-3 1e-3 1e-3"/>
      </geometry>
      <material name="metal">
        <color rgba="0.85 0.85 0.85 1"/>
      </material>
    </visual>
    <collision name="l_thumb_cmc_p_link_col">
      <origin rpy="0 0 0" xyz="0 0 0"/>
      <geometry>
        <mesh filename="package://human_description/meshes/robot_hands/m92u_hand/collision/l_thumb_cmc_p_link.stl" scale="1e-3 1e-3 1e-3"/>
      </geometry>
    </collision>
    <inertial>
      <origin rpy="0.0 0.0 0.0" xyz="0.0037146239 0.0 0.025714396"/>
      <mass value="0.0001"/>
      <inertia ixx="1.1564874e-05" ixy="0.0" ixz="9.8057604e-07" iyy="1.2950704e-05" iyz="0.0" izz="4.7469757e-06"/>
    </inertial>
  </link>
  <joint name="l_thumb_cmc_p_joint" type="revolute">
    <parent link="l_thumb_cmc_y_link"/>
    <child link="l_thumb_cmc_p_link"/>
    <origin rpy="6.98131688888889e-09 1.0556553987442223 1.5707963" xyz="0.0 0.010222 -0.001249999"/>
    <axis xyz="0 1 0"/>
    <limit effort="5.0" lower="-0.9581857593448869" upper="0.0" velocity="1.0"/>
    <dynamics damping="0.05" friction="0.2"/>
  </joint>
  <link name="l_thumb_mcp_link">
    <visual name="l_thumb_mcp_link_vis">
      <origin rpy="0 0 0" xyz="0 0 0"/>
      <geometry>
        <mesh filename="package://human_description/meshes/robot_hands/m92u_hand/visual/l_thumb_mcp_link.stl" scale="1e-3 1e-3 1e-3"/>
      </geometry>
      <material name="metal">
        <color rgba="0.85 0.85 0.85 1"/>
      </material>
    </visual>
    <collision name="l_thumb_mcp_link_col">
      <origin rpy="0 0 0" xyz="0 0 0"/>
      <geometry>
        <mesh filename="package://human_description/meshes/robot_hands/m92u_hand/collision/l_thumb_mcp_link.stl" scale="1e-3 1e-3 1e-3"/>
      </geometry>
    </collision>
    <inertial>
      <origin rpy="0.0 0.0 0.0" xyz="0.0034051517 0 0.010727105"/>
      <mass value="0.0001"/>
      <inertia ixx="6.6016669e-07" ixy="0.0" ixz="-1.9329706e-08" iyy="6.3533864e-07" iyz="0.0" izz="6.546447e-07"/>
    </inertial>
  </link>
  <joint name="l_thumb_mcp_joint" type="revolute">
    <parent link="l_thumb_cmc_p_link"/>
    <child link="l_thumb_mcp_link"/>
    <origin rpy="0.0 0.1292803752142889 0.0" xyz="0.0 0.0 0.061208"/>
    <axis xyz="0 1 0"/>
    <limit effort="5.0" lower="-1.0000736613927508" upper="0.0" velocity="1.0"/>
    <dynamics damping="0.05" friction="0.2"/>
    <mimic joint="l_thumb_cmc_p_joint" multiplier="1.257" offset="0"/>
  </joint>
  <link name="l_thumb_ip_link">
    <visual name="l_thumb_ip_link_vis">
      <origin rpy="0 0 0" xyz="0 0 0"/>
      <geometry>
        <mesh filename="package://human_description/meshes/robot_hands/m92u_hand/visual/l_thumb_ip_link.stl" scale="1e-3 1e-3 1e-3"/>
      </geometry>
      <material name="metal">
        <color rgba="0.85 0.85 0.85 1"/>
      </material>
    </visual>
    <collision name="l_thumb_ip_link_col">
      <origin rpy="0 0 0" xyz="0 0 0"/>
      <geometry>
        <mesh filename="package://human_description/meshes/robot_hands/m92u_hand/collision/l_thumb_ip_link.stl" scale="1e-3 1e-3 1e-3"/>
      </geometry>
    </collision>
    <inertial>
      <origin rpy="0.0 0.0 0.0" xyz="0.00058212386 4.4266405e-06 0.014881067"/>
      <mass value="0.0001"/>
      <inertia ixx="1.0204087e-06" ixy="-8.9029655e-11" ixz="7.0098201e-08" iyy="9.9146034e-07" iyz="1.7085357e-10" izz="3.1951504e-07"/>
    </inertial>
  </link>
  <joint name="l_thumb_ip_joint" type="revolute">
    <parent link="l_thumb_mcp_link"/>
    <child link="l_thumb_ip_link"/>
    <origin rpy="0.0 0.030171506264555555 0.0" xyz="0.0 0.0 0.021998"/>
    <axis xyz="0 1 0"/>
    <limit effort="5.0" lower="-1.0000736613927508" upper="0.0" velocity="1.0"/>
    <dynamics damping="0.05" friction="0.2"/>
    <mimic joint="l_thumb_cmc_p_joint" multiplier="1.009" offset="0"/>
  </joint>
  <link name="l_index_mcp_link">
    <visual name="l_index_mcp_link_vis">
      <origin rpy="0 0 0" xyz="0 0 0"/>
      <geometry>
        <mesh filename="package://human_description/meshes/robot_hands/m92u_hand/visual/l_index_mcp_link.stl" scale="1e-3 1e-3 1e-3"/>
      </geometry>
      <material name="metal">
        <color rgba="0.85 0.85 0.85 1"/>
      </material>
    </visual>
    <collision name="l_index_mcp_link_col">
      <origin rpy="0 0 0" xyz="0 0 0"/>
      <geometry>
        <mesh filename="package://human_description/meshes/robot_hands/m92u_hand/collision/l_index_mcp_link.stl" scale="1e-3 1e-3 1e-3"/>
      </geometry>
    </collision>
    <inertial>
      <origin rpy="0 0 0" xyz="0.0024318988 -3.328481e-07 0.010028137"/>
      <mass value="0.0001"/>
      <inertia ixx="1.1533308e-06" ixy="-1.327215e-11" ixz="-2.5106055e-08" iyy="1.1732561e-06" iyz="-2.2192538e-11" izz="5.6009882e-07"/>
    </inertial>
  </link>
  <joint name="l_index_mcp_joint" type="revolute">
    <parent link="l_hand_palm_link"/>
    <child link="l_index_mcp_link"/>
    <origin rpy="-0.05341929150455556 -0.1994370248941111 0.010576695086666667" xyz="0.0098 0.03651 0.1371306"/>
    <axis xyz="0 1 0"/>
    <limit effort="5.0" lower="-1.509709802975095" upper="0.0" velocity="1.0"/>
    <dynamics damping="0.05" friction="0.2"/>
  </joint>
  <link name="l_index_pip_link">
    <visual name="l_index_pip_link_vis">
      <origin rpy="0 0 0" xyz="0 0 0"/>
      <geometry>
        <mesh filename="package://human_description/meshes/robot_hands/m92u_hand/visual/l_index_pip_link.stl" scale="1e-3 1e-3 1e-3"/>
      </geometry>
      <material name="metal">
        <color rgba="0.85 0.85 0.85 1"/>
      </material>
    </visual>
    <collision name="l_index_pip_link_col">
      <origin rpy="0 0 0" xyz="0 0 0"/>
      <geometry>
        <mesh filename="package://human_description/meshes/robot_hands/m92u_hand/collision/l_index_pip_link.stl" scale="1e-3 1e-3 1e-3"/>
      </geometry>
    </collision>
    <inertial>
      <origin rpy="0 0 0" xyz="-0.0021920592 2.81739e-06 0.023240314"/>
      <mass value="0.0001"/>
      <inertia ixx="2.8856205e-06" ixy="-5.3997072e-11" ixz="-2.4954332e-07" iyy="2.8726183e-06" iyz="-9.9600212e-11" izz="3.6244504e-07"/>
    </inertial>
  </link>
  <joint name="l_index_pip_joint" type="revolute">
    <parent link="l_index_mcp_link"/>
    <child link="l_index_pip_link"/>
    <origin rpy="0.0 -0.05016320530757778 0.0" xyz="0.0 0.0 0.0310058"/>
    <axis xyz="0 1 0"/>
    <limit effort="5.0" lower="0.0" upper="3.5831609543443586" velocity="1.0"/>
    <dynamics damping="0.05" friction="0.2"/>
    <mimic joint="l_index_mcp_joint" multiplier="0.9845" offset="0"/>
  </joint>
  <link name="l_middle_mcp_link">
    <visual name="l_middle_mcp_link_vis">
      <origin rpy="0 0 0" xyz="0 0 0"/>
      <geometry>
        <mesh filename="package://human_description/meshes/robot_hands/m92u_hand/visual/l_middle_mcp_link.stl" scale="1e-3 1e-3 1e-3"/>
      </geometry>
      <material name="metal">
        <color rgba="0.85 0.85 0.85 1"/>
      </material>
    </visual>
    <collision name="l_middle_mcp_link_col">
      <origin rpy="0 0 0" xyz="0 0 0"/>
      <geometry>
        <mesh filename="package://human_description/meshes/robot_hands/m92u_hand/collision/l_middle_mcp_link.stl" scale="1e-3 1e-3 1e-3"/>
      </geometry>
    </collision>
    <inertial>
      <origin rpy="0 0 0" xyz="0.0024318988 -3.328481e-07 0.010028137"/>
      <mass value="0.0001"/>
      <inertia ixx="1.1533308e-06" ixy="-1.327215e-11" ixz="-2.5106055e-08" iyy="1.1732561e-06" iyz="-2.2192538e-11" izz="5.6009882e-07"/>
    </inertial>
  </link>
  <joint name="l_middle_mcp_joint" type="revolute">
    <parent link="l_hand_palm_link"/>
    <child link="l_middle_mcp_link"/>
    <origin rpy="0.0 -0.19971453224044444 0.0" xyz="0.0098 0.0110499 0.1382999"/>
    <axis xyz="0 1 0"/>
    <limit effort="5.0" lower="-1.509709802975095" upper="0.0" velocity="1.0"/>
    <dynamics damping="0.05" friction="0.2"/>
  </joint>
  <link name="l_middle_pip_link">
    <visual name="l_middle_pip_link_vis">
      <origin rpy="0 0 0" xyz="0 0 0"/>
      <geometry>
        <mesh filename="package://human_description/meshes/robot_hands/m92u_hand/visual/l_middle_pip_link.stl" scale="1e-3 1e-3 1e-3"/>
      </geometry>
      <material name="metal">
        <color rgba="0.85 0.85 0.85 1"/>
      </material>
    </visual>
    <collision name="l_middle_pip_link_col">
      <origin rpy="0 0 0" xyz="0 0 0"/>
      <geometry>
        <mesh filename="package://human_description/meshes/robot_hands/m92u_hand/collision/l_middle_pip_link.stl" scale="1e-3 1e-3 1e-3"/>
      </geometry>
    </collision>
    <inertial>
      <origin rpy="0 0 0" xyz="-0.0021920592 2.81739e-06 0.023240314"/>
      <mass value="0.0001"/>
      <inertia ixx="2.8856205e-06" ixy="-5.3997072e-11" ixz="-2.4954332e-07" iyy="2.8726183e-06" iyz="-9.9600212e-11" izz="3.6244504e-07"/>
    </inertial>
  </link>
  <joint name="l_middle_pip_joint" type="revolute">
    <parent link="l_middle_mcp_link"/>
    <child link="l_middle_pip_link"/>
    <origin rpy="0.0 -0.05016320530757778 0.0" xyz="0.0 0.0 0.0310058"/>
    <axis xyz="0 1 0"/>
    <limit effort="5.0" lower="0.0" upper="3.5831609543443586" velocity="1.0"/>
    <dynamics damping="0.05" friction="0.2"/>
    <mimic joint="l_middle_mcp_joint" multiplier="0.9845" offset="0"/>
  </joint>
  <link name="l_ring_mcp_link">
    <visual name="l_ring_mcp_link_vis">
      <origin rpy="0 0 0" xyz="0 0 0"/>
      <geometry>
        <mesh filename="package://human_description/meshes/robot_hands/m92u_hand/visual/l_ring_mcp_link.stl" scale="1e-3 1e-3 1e-3"/>
      </geometry>
      <material name="metal">
        <color rgba="0.85 0.85 0.85 1"/>
      </material>
    </visual>
    <collision name="l_ring_mcp_link_col">
      <origin rpy="0 0 0" xyz="0 0 0"/>
      <geometry>
        <mesh filename="package://human_description/meshes/robot_hands/m92u_hand/collision/l_ring_mcp_link.stl" scale="1e-3 1e-3 1e-3"/>
      </geometry>
    </collision>
    <inertial>
      <origin rpy="0 0 0" xyz="0.0024318988 -3.328481e-07 0.010028137"/>
      <mass value="0.0001"/>
      <inertia ixx="1.1533308e-06" ixy="-1.327215e-11" ixz="-2.5106055e-08" iyy="1.1732561e-06" iyz="-2.2192538e-11" izz="5.6009882e-07"/>
    </inertial>
  </link>
  <joint name="l_ring_mcp_joint" type="revolute">
    <parent link="l_hand_palm_link"/>
    <child link="l_ring_mcp_link"/>
    <origin rpy="0.05341927405126334 -0.1994370248941111 -0.010592403049666667" xyz="0.0098 -0.01446388 0.13813451"/>
    <axis xyz="0 1 0"/>
    <limit effort="5.0" lower="-1.509709802975095" upper="0.0" velocity="1.0"/>
    <dynamics damping="0.05" friction="0.2"/>
  </joint>
  <link name="l_ring_pip_link">
    <visual name="l_ring_pip_link_vis">
      <origin rpy="0 0 0" xyz="0 0 0"/>
      <geometry>
        <mesh filename="package://human_description/meshes/robot_hands/m92u_hand/visual/l_ring_pip_link.stl" scale="1e-3 1e-3 1e-3"/>
      </geometry>
      <material name="metal">
        <color rgba="0.85 0.85 0.85 1"/>
      </material>
    </visual>
    <collision name="l_ring_pip_link_col">
      <origin rpy="0 0 0" xyz="0 0 0"/>
      <geometry>
        <mesh filename="package://human_description/meshes/robot_hands/m92u_hand/collision/l_ring_pip_link.stl" scale="1e-3 1e-3 1e-3"/>
      </geometry>
    </collision>
    <inertial>
      <origin rpy="0 0 0" xyz="-0.0021920592 2.81739e-06 0.023240314"/>
      <mass value="0.0001"/>
      <inertia ixx="2.8856205e-06" ixy="-5.3997072e-11" ixz="-2.4954332e-07" iyy="2.8726183e-06" iyz="-9.9600212e-11" izz="3.6244504e-07"/>
    </inertial>
  </link>
  <joint name="l_ring_pip_joint" type="revolute">
    <parent link="l_ring_mcp_link"/>
    <child link="l_ring_pip_link"/>
    <origin rpy="0.0 -0.05016320530757778 0.0" xyz="0.0 0.0 0.0310058"/>
    <axis xyz="0 1 0"/>
    <limit effort="5.0" lower="0.0" upper="3.5831609543443586" velocity="1.0"/>
    <dynamics damping="0.05" friction="0.2"/>
    <mimic joint="l_ring_mcp_joint" multiplier="0.9845" offset="0"/>
  </joint>
  <link name="l_pinky_mcp_link">
    <visual name="l_pinky_mcp_link_vis">
      <origin rpy="0 0 0" xyz="0 0 0"/>
      <geometry>
        <mesh filename="package://human_description/meshes/robot_hands/m92u_hand/visual/l_pinky_mcp_link.stl" scale="1e-3 1e-3 1e-3"/>
      </geometry>
      <material name="metal">
        <color rgba="0.85 0.85 0.85 1"/>
      </material>
    </visual>
    <collision name="l_pinky_mcp_link_col">
      <origin rpy="0 0 0" xyz="0 0 0"/>
      <geometry>
        <mesh filename="package://human_description/meshes/robot_hands/m92u_hand/collision/l_pinky_mcp_link.stl" scale="1e-3 1e-3 1e-3"/>
      </geometry>
    </collision>
    <inertial>
      <origin rpy="0 0 0" xyz="0.0024318988 -3.328481e-07 0.010028137"/>
      <mass value="0.0001"/>
      <inertia ixx="1.1533308e-06" ixy="-1.327215e-11" ixz="-2.5106055e-08" iyy="1.1732561e-06" iyz="-2.2192538e-11" izz="5.6009882e-07"/>
    </inertial>
  </link>
  <joint name="l_pinky_mcp_joint" type="revolute">
    <parent link="l_hand_palm_link"/>
    <child link="l_pinky_mcp_link"/>
    <origin rpy="0.1068141484 -0.19860101219666665 -0.021153390173333335" xyz="0.0098 -0.0398034 0.13514012"/>
    <axis xyz="0 1 0"/>
    <limit effort="5.0" lower="-1.509709802975095" upper="0.0" velocity="1.0"/>
    <dynamics damping="0.05" friction="0.2"/>
  </joint>
  <link name="l_pinky_pip_link">
    <visual name="l_pinky_pip_link_vis">
      <origin rpy="0 0 0" xyz="0 0 0"/>
      <geometry>
        <mesh filename="package://human_description/meshes/robot_hands/m92u_hand/visual/l_pinky_pip_link.stl" scale="1e-3 1e-3 1e-3"/>
      </geometry>
      <material name="metal">
        <color rgba="0.85 0.85 0.85 1"/>
      </material>
    </visual>
    <collision name="l_pinky_pip_link_col">
      <origin rpy="0 0 0" xyz="0 0 0"/>
      <geometry>
        <mesh filename="package://human_description/meshes/robot_hands/m92u_hand/collision/l_pinky_pip_link.stl" scale="1e-3 1e-3 1e-3"/>
      </geometry>
    </collision>
    <inertial>
      <origin rpy="0 0 0" xyz="-0.0021920592 2.81739e-06 0.023240314"/>
      <mass value="0.0001"/>
      <inertia ixx="2.8856205e-06" ixy="-5.3997072e-11" ixz="-2.4954332e-07" iyy="2.8726183e-06" iyz="-9.9600212e-11" izz="3.6244504e-07"/>
    </inertial>
  </link>
  <joint name="l_pinky_pip_joint" type="revolute">
    <parent link="l_pinky_mcp_link"/>
    <child link="l_pinky_pip_link"/>
    <origin rpy="0.0 -0.05016320530757778 0.0" xyz="0.0 0.0 0.0310058"/>
    <axis xyz="0 1 0"/>
    <limit effort="5.0" lower="0.0" upper="3.5831609543443586" velocity="1.0"/>
    <dynamics damping="0.05" friction="0.2"/>
    <mimic joint="l_pinky_mcp_joint" multiplier="0.9845" offset="0"/>
  </joint>
  <ros2_control name="l_hand_system" type="system">
    <hardware>
      <plugin>mujoco_ros2_control/MujocoSystem</plugin>
    </hardware>
    <joint name="l_thumb_cmc_y_joint">
      <param name="initial_position">0.0</param>
      <command_interface name="position"/>
      <state_interface name="position">
        <param name="initial_value">0.0</param>
      </state_interface>
      <state_interface name="velocity"/>
      <state_interface name="effort"/>
    </joint>
    <transmission name="l_thumb_cmc_y_transmission">
      <plugin>transmission_interface/SimpleTransmission</plugin>
      <joint name="l_thumb_cmc_y_joint" role="joint1">
        <mechanical_reduction>1.0</mechanical_reduction>
        <offset>0</offset>
      </joint>
      <actuator name="l_thumb_cmc_y_actuator" role="actuator1">
        <mechanical_reduction>1.0</mechanical_reduction>
        <offset>0</offset>
      </actuator>
    </transmission>
    <joint name="l_thumb_cmc_p_joint">
      <param name="initial_position">0.0</param>
      <command_interface name="position"/>
      <state_interface name="position">
        <param name="initial_value">0.0</param>
      </state_interface>
      <state_interface name="velocity"/>
      <state_interface name="effort"/>
    </joint>
    <transmission name="l_thumb_cmc_p_transmission">
      <plugin>transmission_interface/SimpleTransmission</plugin>
      <joint name="l_thumb_cmc_p_joint" role="joint1">
        <mechanical_reduction>1.0</mechanical_reduction>
        <offset>0</offset>
      </joint>
      <actuator name="l_thumb_cmc_p_actuator" role="actuator1">
        <mechanical_reduction>1.0</mechanical_reduction>
        <offset>0</offset>
      </actuator>
    </transmission>
    <joint name="l_thumb_mcp_joint">
      <param name="initial_position">0.0</param>
      <param name="mimic">l_thumb_cmc_p_joint</param>
      <param name="multiplier">1</param>
      <command_interface name="position"/>
      <state_interface name="position">
        <param name="initial_value">0.0</param>
      </state_interface>
      <state_interface name="velocity"/>
      <state_interface name="effort"/>
    </joint>
    <joint name="l_thumb_ip_joint">
      <param name="initial_position">0.0</param>
      <param name="mimic">l_thumb_cmc_p_joint</param>
      <param name="multiplier">1</param>
      <command_interface name="position"/>
      <state_interface name="position">
        <param name="initial_value">0.0</param>
      </state_interface>
      <state_interface name="velocity"/>
      <state_interface name="effort"/>
    </joint>
    <joint name="l_index_mcp_joint">
      <param name="initial_position">0.0</param>
      <command_interface name="position"/>
      <state_interface name="position">
        <param name="initial_value">0.0</param>
      </state_interface>
      <state_interface name="velocity"/>
      <state_interface name="effort"/>
    </joint>
    <transmission name="l_index_mcp_transmission">
      <plugin>transmission_interface/SimpleTransmission</plugin>
      <joint name="l_index_mcp_joint" role="joint1">
        <mechanical_reduction>1.0</mechanical_reduction>
        <offset>0</offset>
      </joint>
      <actuator name="l_index_mcp_actuator" role="actuator1">
        <mechanical_reduction>1.0</mechanical_reduction>
        <offset>0</offset>
      </actuator>
    </transmission>
    <joint name="l_index_pip_joint">
      <param name="initial_position">0.0</param>
      <param name="mimic">l_index_mcp_joint</param>
      <param name="multiplier">1</param>
      <command_interface name="position"/>
      <state_interface name="position">
        <param name="initial_value">0.0</param>
      </state_interface>
      <state_interface name="velocity"/>
      <state_interface name="effort"/>
    </joint>
    <joint name="l_middle_mcp_joint">
      <param name="initial_position">0.0</param>
      <command_interface name="position"/>
      <state_interface name="position">
        <param name="initial_value">0.0</param>
      </state_interface>
      <state_interface name="velocity"/>
      <state_interface name="effort"/>
    </joint>
    <transmission name="l_middle_mcp_transmission">
      <plugin>transmission_interface/SimpleTransmission</plugin>
      <joint name="l_middle_mcp_joint" role="joint1">
        <mechanical_reduction>1.0</mechanical_reduction>
        <offset>0</offset>
      </joint>
      <actuator name="l_middle_mcp_actuator" role="actuator1">
        <mechanical_reduction>1.0</mechanical_reduction>
        <offset>0</offset>
      </actuator>
    </transmission>
    <joint name="l_middle_pip_joint">
      <param name="initial_position">0.0</param>
      <param name="mimic">l_middle_mcp_joint</param>
      <param name="multiplier">1</param>
      <command_interface name="position"/>
      <state_interface name="position">
        <param name="initial_value">0.0</param>
      </state_interface>
      <state_interface name="velocity"/>
      <state_interface name="effort"/>
    </joint>
    <joint name="l_pinky_mcp_joint">
      <param name="initial_position">0.0</param>
      <command_interface name="position"/>
      <state_interface name="position">
        <param name="initial_value">0.0</param>
      </state_interface>
      <state_interface name="velocity"/>
      <state_interface name="effort"/>
    </joint>
    <transmission name="l_pinky_mcp_transmission">
      <plugin>transmission_interface/SimpleTransmission</plugin>
      <joint name="l_pinky_mcp_joint" role="joint1">
        <mechanical_reduction>1.0</mechanical_reduction>
        <offset>0</offset>
      </joint>
      <actuator name="l_pinky_mcp_actuator" role="actuator1">
        <mechanical_reduction>1.0</mechanical_reduction>
        <offset>0</offset>
      </actuator>
    </transmission>
    <joint name="l_pinky_pip_joint">
      <param name="initial_position">0.0</param>
      <param name="mimic">l_pinky_mcp_joint</param>
      <param name="multiplier">1</param>
      <command_interface name="position"/>
      <state_interface name="position">
        <param name="initial_value">0.0</param>
      </state_interface>
      <state_interface name="velocity"/>
      <state_interface name="effort"/>
    </joint>
    <joint name="l_ring_mcp_joint">
      <param name="initial_position">0.0</param>
      <command_interface name="position"/>
      <state_interface name="position">
        <param name="initial_value">0.0</param>
      </state_interface>
      <state_interface name="velocity"/>
      <state_interface name="effort"/>
    </joint>
    <transmission name="l_ring_mcp_transmission">
      <plugin>transmission_interface/SimpleTransmission</plugin>
      <joint name="l_ring_mcp_joint" role="joint1">
        <mechanical_reduction>1.0</mechanical_reduction>
        <offset>0</offset>
      </joint>
      <actuator name="l_ring_mcp_actuator" role="actuator1">
        <mechanical_reduction>1.0</mechanical_reduction>
        <offset>0</offset>
      </actuator>
    </transmission>
    <joint name="l_ring_pip_joint">
      <param name="initial_position">0.0</param>
      <param name="mimic">l_ring_mcp_joint</param>
      <param name="multiplier">1</param>
      <command_interface name="position"/>
      <state_interface name="position">
        <param name="initial_value">0.0</param>
      </state_interface>
      <state_interface name="velocity"/>
      <state_interface name="effort"/>
    </joint>
  </ros2_control>
  <link name="r_hand_palm_link">
    <visual name="r_hand_palm_link_vis">
      <origin rpy="0 0 0" xyz="0 0 0"/>
      <geometry>
        <sphere radius="0.005"/>
      </geometry>
      <material name="yellow">
        <color rgba="0.9 1.0 0.0 1.0"/>
      </material>
    </visual>
    <collision name="r_hand_palm_link_col">
      <origin rpy="0 0 0" xyz="0 0 0"/>
      <geometry>
        <sphere radius="0.005"/>
      </geometry>
    </collision>
    <inertial>
      <origin rpy="0. 0. 0." xyz="0. 0. 0."/>
      <mass value="1e-05"/>
      <inertia ixx="8.333333333333334e-11" ixy="0" ixz="0" iyy="8.333333333333334e-11" iyz="0" izz="1.25e-10"/>
    </inertial>
  </link>
  <joint name="r_hand_palm_fixed_joint" type="fixed">
    <parent link="r_end_effector_link"/>
    <child link="r_hand_palm_link"/>
    <origin rpy="3.1415926 0.0 1.5707963" xyz="-2.2e-11 -2.45e-10 -0.1002"/>
    <axis xyz="0 0 1"/>
  </joint>
  <link name="r_thumb_cmc_y_link">
    <visual name="r_thumb_cmc_y_link_vis">
      <origin rpy="0 0 0" xyz="0 0 0"/>
      <geometry>
        <mesh filename="package://human_description/meshes/robot_hands/m92u_hand/visual/r_thumb_cmc_y_link.stl" scale="1e-3 1e-3 1e-3"/>
      </geometry>
      <material name="metal">
        <color rgba="0.85 0.85 0.85 1"/>
      </material>
    </visual>
    <collision name="r_thumb_cmc_y_link_col">
      <origin rpy="0 0 0" xyz="0 0 0"/>
      <geometry>
        <mesh filename="package://human_description/meshes/robot_hands/m92u_hand/collision/r_thumb_cmc_y_link.stl" scale="1e-3 1e-3 1e-3"/>
      </geometry>
    </collision>
    <inertial>
      <origin rpy="0.0 0.0 0.0" xyz="0.0043445795 0.00073516028 0.00092114437"/>
      <mass value="0.0001"/>
      <inertia ixx="1.2807232e-07" ixy="2.6031726e-08" ixz="-9.2990531e-09" iyy="2.0994928e-07" iyz="2.3599758e-09" izz="1.8089779e-07"/>
    </inertial>
  </link>
  <joint name="r_thumb_cmc_y_joint" type="revolute">
    <parent link="r_hand_palm_link"/>
    <child link="r_thumb_cmc_y_link"/>
    <origin rpy="6.98131688888889e-09 -4.188790133333333e-08 -0.17452838436624443" xyz="0.01285999 0.030499 0.0422"/>
    <axis xyz="0 0 1"/>
    <limit effort="5.0" lower="-1.5707963267948966" upper="0.0" velocity="1.0"/>
    <dynamics damping="0.05" friction="0.2"/>
  </joint>
  <link name="r_thumb_cmc_p_link">
    <visual name="r_thumb_cmc_p_link_vis">
      <origin rpy="0 0 0" xyz="0 0 0"/>
      <geometry>
        <mesh filename="package://human_description/meshes/robot_hands/m92u_hand/visual/r_thumb_cmc_p_link.stl" scale="1e-3 1e-3 1e-3"/>
      </geometry>
      <material name="metal">
        <color rgba="0.85 0.85 0.85 1"/>
      </material>
    </visual>
    <collision name="r_thumb_cmc_p_link_col">
      <origin rpy="0 0 0" xyz="0 0 0"/>
      <geometry>
        <mesh filename="package://human_description/meshes/robot_hands/m92u_hand/collision/r_thumb_cmc_p_link.stl" scale="1e-3 1e-3 1e-3"/>
      </geometry>
    </collision>
    <inertial>
      <origin rpy="0.0 0.0 0.0" xyz="0.0037146239 0.0 0.025714396"/>
      <mass value="0.0001"/>
      <inertia ixx="1.1564874e-05" ixy="0.0" ixz="9.8057604e-07" iyy="1.2950704e-05" iyz="0.0" izz="4.7469757e-06"/>
    </inertial>
  </link>
  <joint name="r_thumb_cmc_p_joint" type="revolute">
    <parent link="r_thumb_cmc_y_link"/>
    <child link="r_thumb_cmc_p_link"/>
    <origin rpy="6.98131688888889e-09 1.0556553987442223 1.5707963" xyz="0.0 0.010222 -0.001249999"/>
    <axis xyz="0 1 0"/>
    <limit effort="5.0" lower="-0.9581857593448869" upper="0.0" velocity="1.0"/>
    <dynamics damping="0.05" friction="0.2"/>
  </joint>
  <link name="r_thumb_mcp_link">
    <visual name="r_thumb_mcp_link_vis">
      <origin rpy="0 0 0" xyz="0 0 0"/>
      <geometry>
        <mesh filename="package://human_description/meshes/robot_hands/m92u_hand/visual/r_thumb_mcp_link.stl" scale="1e-3 1e-3 1e-3"/>
      </geometry>
      <material name="metal">
        <color rgba="0.85 0.85 0.85 1"/>
      </material>
    </visual>
    <collision name="r_thumb_mcp_link_col">
      <origin rpy="0 0 0" xyz="0 0 0"/>
      <geometry>
        <mesh filename="package://human_description/meshes/robot_hands/m92u_hand/collision/r_thumb_mcp_link.stl" scale="1e-3 1e-3 1e-3"/>
      </geometry>
    </collision>
    <inertial>
      <origin rpy="0.0 0.0 0.0" xyz="0.0034051517 0 0.010727105"/>
      <mass value="0.0001"/>
      <inertia ixx="6.6016669e-07" ixy="0.0" ixz="-1.9329706e-08" iyy="6.3533864e-07" iyz="0.0" izz="6.546447e-07"/>
    </inertial>
  </link>
  <joint name="r_thumb_mcp_joint" type="revolute">
    <parent link="r_thumb_cmc_p_link"/>
    <child link="r_thumb_mcp_link"/>
    <origin rpy="0.0 0.1292803752142889 0.0" xyz="0.0 0.0 0.061208"/>
    <axis xyz="0 1 0"/>
    <limit effort="5.0" lower="-1.0000736613927508" upper="0.0" velocity="1.0"/>
    <dynamics damping="0.05" friction="0.2"/>
    <mimic joint="r_thumb_cmc_p_joint" multiplier="1.257" offset="0"/>
  </joint>
  <link name="r_thumb_ip_link">
    <visual name="r_thumb_ip_link_vis">
      <origin rpy="0 0 0" xyz="0 0 0"/>
      <geometry>
        <mesh filename="package://human_description/meshes/robot_hands/m92u_hand/visual/r_thumb_ip_link.stl" scale="1e-3 1e-3 1e-3"/>
      </geometry>
      <material name="metal">
        <color rgba="0.85 0.85 0.85 1"/>
      </material>
    </visual>
    <collision name="r_thumb_ip_link_col">
      <origin rpy="0 0 0" xyz="0 0 0"/>
      <geometry>
        <mesh filename="package://human_description/meshes/robot_hands/m92u_hand/collision/r_thumb_ip_link.stl" scale="1e-3 1e-3 1e-3"/>
      </geometry>
    </collision>
    <inertial>
      <origin rpy="0.0 0.0 0.0" xyz="0.00058212386 4.4266405e-06 0.014881067"/>
      <mass value="0.0001"/>
      <inertia ixx="1.0204087e-06" ixy="-8.9029655e-11" ixz="7.0098201e-08" iyy="9.9146034e-07" iyz="1.7085357e-10" izz="3.1951504e-07"/>
    </inertial>
  </link>
  <joint name="r_thumb_ip_joint" type="revolute">
    <parent link="r_thumb_mcp_link"/>
    <child link="r_thumb_ip_link"/>
    <origin rpy="0.0 0.030171506264555555 0.0" xyz="0.0 0.0 0.021998"/>
    <axis xyz="0 1 0"/>
    <limit effort="5.0" lower="-1.0000736613927508" upper="0.0" velocity="1.0"/>
    <dynamics damping="0.05" friction="0.2"/>
    <mimic joint="r_thumb_cmc_p_joint" multiplier="1.009" offset="0"/>
  </joint>
  <link name="r_index_mcp_link">
    <visual name="r_index_mcp_link_vis">
      <origin rpy="0 0 0" xyz="0 0 0"/>
      <geometry>
        <mesh filename="package://human_description/meshes/robot_hands/m92u_hand/visual/r_index_mcp_link.stl" scale="1e-3 1e-3 1e-3"/>
      </geometry>
      <material name="metal">
        <color rgba="0.85 0.85 0.85 1"/>
      </material>
    </visual>
    <collision name="r_index_mcp_link_col">
      <origin rpy="0 0 0" xyz="0 0 0"/>
      <geometry>
        <mesh filename="package://human_description/meshes/robot_hands/m92u_hand/collision/r_index_mcp_link.stl" scale="1e-3 1e-3 1e-3"/>
      </geometry>
    </collision>
    <inertial>
      <origin rpy="0 0 0" xyz="-0.0024318988 3.328481e-07 0.010028137"/>
      <mass value="0.0001"/>
      <inertia ixx="1.1533308e-06" ixy="-1.327215e-11" ixz="2.5106055e-08" iyy="1.1732561e-06" iyz="2.2192538e-11" izz="5.6009882e-07"/>
    </inertial>
  </link>
  <joint name="r_index_mcp_joint" type="revolute">
    <parent link="r_hand_palm_link"/>
    <child link="r_index_mcp_link"/>
    <origin rpy="-0.05341929150455556 0.1994370248941111 -0.010576695086666667" xyz="-0.0098 0.03651 0.1371306"/>
    <axis xyz="0 1 0"/>
    <limit effort="5.0" lower="0.0" upper="1.509709802975095" velocity="1.0"/>
    <dynamics damping="0.05" friction="0.2"/>
  </joint>
  <link name="r_index_pip_link">
    <visual name="r_index_pip_link_vis">
      <origin rpy="0 0 0" xyz="0 0 0"/>
      <geometry>
        <mesh filename="package://human_description/meshes/robot_hands/m92u_hand/visual/r_index_pip_link.stl" scale="1e-3 1e-3 1e-3"/>
      </geometry>
      <material name="metal">
        <color rgba="0.85 0.85 0.85 1"/>
      </material>
    </visual>
    <collision name="r_index_pip_link_col">
      <origin rpy="0 0 0" xyz="0 0 0"/>
      <geometry>
        <mesh filename="package://human_description/meshes/robot_hands/m92u_hand/collision/r_index_pip_link.stl" scale="1e-3 1e-3 1e-3"/>
      </geometry>
    </collision>
    <inertial>
      <origin rpy="0 0 0" xyz="-0.0021920592 2.81739e-06 0.023240314"/>
      <mass value="0.0001"/>
      <inertia ixx="2.8856205e-06" ixy="-5.3997072e-11" ixz="-2.4954332e-07" iyy="2.8726183e-06" iyz="-9.9600212e-11" izz="3.6244504e-07"/>
    </inertial>
  </link>
  <joint name="r_index_pip_joint" type="revolute">
    <parent link="r_index_mcp_link"/>
    <child link="r_index_pip_link"/>
    <origin rpy="0.0 0.05016320530757778 0.0" xyz="0.0 0.0 0.0310058"/>
    <axis xyz="0 1 0"/>
    <limit effort="5.0" lower="0.0" upper="3.5831609543443586" velocity="1.0"/>
    <dynamics damping="0.05" friction="0.2"/>
    <mimic joint="r_index_mcp_joint" multiplier="0.9845" offset="0"/>
  </joint>
  <link name="r_middle_mcp_link">
    <visual name="r_middle_mcp_link_vis">
      <origin rpy="0 0 0" xyz="0 0 0"/>
      <geometry>
        <mesh filename="package://human_description/meshes/robot_hands/m92u_hand/visual/r_middle_mcp_link.stl" scale="1e-3 1e-3 1e-3"/>
      </geometry>
      <material name="metal">
        <color rgba="0.85 0.85 0.85 1"/>
      </material>
    </visual>
    <collision name="r_middle_mcp_link_col">
      <origin rpy="0 0 0" xyz="0 0 0"/>
      <geometry>
        <mesh filename="package://human_description/meshes/robot_hands/m92u_hand/collision/r_middle_mcp_link.stl" scale="1e-3 1e-3 1e-3"/>
      </geometry>
    </collision>
    <inertial>
      <origin rpy="0 0 0" xyz="-0.0024318988 3.328481e-07 0.010028137"/>
      <mass value="0.0001"/>
      <inertia ixx="1.1533308e-06" ixy="-1.327215e-11" ixz="2.5106055e-08" iyy="1.1732561e-06" iyz="2.2192538e-11" izz="5.6009882e-07"/>
    </inertial>
  </link>
  <joint name="r_middle_mcp_joint" type="revolute">
    <parent link="r_hand_palm_link"/>
    <child link="r_middle_mcp_link"/>
    <origin rpy="0.0 0.19971453224044444 0.0" xyz="-0.0098 0.0110499 0.1382999"/>
    <axis xyz="0 1 0"/>
    <limit effort="5.0" lower="0.0" upper="1.509709802975095" velocity="1.0"/>
    <dynamics damping="0.05" friction="0.2"/>
  </joint>
  <link name="r_middle_pip_link">
    <visual name="r_middle_pip_link_vis">
      <origin rpy="0 0 0" xyz="0 0 0"/>
      <geometry>
        <mesh filename="package://human_description/meshes/robot_hands/m92u_hand/visual/r_middle_pip_link.stl" scale="1e-3 1e-3 1e-3"/>
      </geometry>
      <material name="metal">
        <color rgba="0.85 0.85 0.85 1"/>
      </material>
    </visual>
    <collision name="r_middle_pip_link_col">
      <origin rpy="0 0 0" xyz="0 0 0"/>
      <geometry>
        <mesh filename="package://human_description/meshes/robot_hands/m92u_hand/collision/r_middle_pip_link.stl" scale="1e-3 1e-3 1e-3"/>
      </geometry>
    </collision>
    <inertial>
      <origin rpy="0 0 0" xyz="-0.0021920592 2.81739e-06 0.023240314"/>
      <mass value="0.0001"/>
      <inertia ixx="2.8856205e-06" ixy="-5.3997072e-11" ixz="-2.4954332e-07" iyy="2.8726183e-06" iyz="-9.9600212e-11" izz="3.6244504e-07"/>
    </inertial>
  </link>
  <joint name="r_middle_pip_joint" type="revolute">
    <parent link="r_middle_mcp_link"/>
    <child link="r_middle_pip_link"/>
    <origin rpy="0.0 0.05016320530757778 0.0" xyz="0.0 0.0 0.0310058"/>
    <axis xyz="0 1 0"/>
    <limit effort="5.0" lower="0.0" upper="3.5831609543443586" velocity="1.0"/>
    <dynamics damping="0.05" friction="0.2"/>
    <mimic joint="r_middle_mcp_joint" multiplier="0.9845" offset="0"/>
  </joint>
  <link name="r_ring_mcp_link">
    <visual name="r_ring_mcp_link_vis">
      <origin rpy="0 0 0" xyz="0 0 0"/>
      <geometry>
        <mesh filename="package://human_description/meshes/robot_hands/m92u_hand/visual/r_ring_mcp_link.stl" scale="1e-3 1e-3 1e-3"/>
      </geometry>
      <material name="metal">
        <color rgba="0.85 0.85 0.85 1"/>
      </material>
    </visual>
    <collision name="r_ring_mcp_link_col">
      <origin rpy="0 0 0" xyz="0 0 0"/>
      <geometry>
        <mesh filename="package://human_description/meshes/robot_hands/m92u_hand/collision/r_ring_mcp_link.stl" scale="1e-3 1e-3 1e-3"/>
      </geometry>
    </collision>
    <inertial>
      <origin rpy="0 0 0" xyz="-0.0024318988 3.328481e-07 0.010028137"/>
      <mass value="0.0001"/>
      <inertia ixx="1.1533308e-06" ixy="-1.327215e-11" ixz="2.5106055e-08" iyy="1.1732561e-06" iyz="2.2192538e-11" izz="5.6009882e-07"/>
    </inertial>
  </link>
  <joint name="r_ring_mcp_joint" type="revolute">
    <parent link="r_hand_palm_link"/>
    <child link="r_ring_mcp_link"/>
    <origin rpy="0.05341927405126334 0.1994370248941111 0.010592403049666667" xyz="-0.0098 -0.01446388 0.13813451"/>
    <axis xyz="0 1 0"/>
    <limit effort="5.0" lower="0.0" upper="1.509709802975095" velocity="1.0"/>
    <dynamics damping="0.05" friction="0.2"/>
  </joint>
  <link name="r_ring_pip_link">
    <visual name="r_ring_pip_link_vis">
      <origin rpy="0 0 0" xyz="0 0 0"/>
      <geometry>
        <mesh filename="package://human_description/meshes/robot_hands/m92u_hand/visual/r_ring_pip_link.stl" scale="1e-3 1e-3 1e-3"/>
      </geometry>
      <material name="metal">
        <color rgba="0.85 0.85 0.85 1"/>
      </material>
    </visual>
    <collision name="r_ring_pip_link_col">
      <origin rpy="0 0 0" xyz="0 0 0"/>
      <geometry>
        <mesh filename="package://human_description/meshes/robot_hands/m92u_hand/collision/r_ring_pip_link.stl" scale="1e-3 1e-3 1e-3"/>
      </geometry>
    </collision>
    <inertial>
      <origin rpy="0 0 0" xyz="-0.0021920592 2.81739e-06 0.023240314"/>
      <mass value="0.0001"/>
      <inertia ixx="2.8856205e-06" ixy="-5.3997072e-11" ixz="-2.4954332e-07" iyy="2.8726183e-06" iyz="-9.9600212e-11" izz="3.6244504e-07"/>
    </inertial>
  </link>
  <joint name="r_ring_pip_joint" type="revolute">
    <parent link="r_ring_mcp_link"/>
    <child link="r_ring_pip_link"/>
    <origin rpy="0.0 0.05016320530757778 0.0" xyz="0.0 0.0 0.0310058"/>
    <axis xyz="0 1 0"/>
    <limit effort="5.0" lower="0.0" upper="3.5831609543443586" velocity="1.0"/>
    <dynamics damping="0.05" friction="0.2"/>
    <mimic joint="r_ring_mcp_joint" multiplier="0.9845" offset="0"/>
  </joint>
  <link name="r_pinky_mcp_link">
    <visual name="r_pinky_mcp_link_vis">
      <origin rpy="0 0 0" xyz="0 0 0"/>
      <geometry>
        <mesh filename="package://human_description/meshes/robot_hands/m92u_hand/visual/r_pinky_mcp_link.stl" scale="1e-3 1e-3 1e-3"/>
      </geometry>
      <material name="metal">
        <color rgba="0.85 0.85 0.85 1"/>
      </material>
    </visual>
    <collision name="r_pinky_mcp_link_col">
      <origin rpy="0 0 0" xyz="0 0 0"/>
      <geometry>
        <mesh filename="package://human_description/meshes/robot_hands/m92u_hand/collision/r_pinky_mcp_link.stl" scale="1e-3 1e-3 1e-3"/>
      </geometry>
    </collision>
    <inertial>
      <origin rpy="0 0 0" xyz="-0.0024318988 3.328481e-07 0.010028137"/>
      <mass value="0.0001"/>
      <inertia ixx="1.1533308e-06" ixy="-1.327215e-11" ixz="2.5106055e-08" iyy="1.1732561e-06" iyz="2.2192538e-11" izz="5.6009882e-07"/>
    </inertial>
  </link>
  <joint name="r_pinky_mcp_joint" type="revolute">
    <parent link="r_hand_palm_link"/>
    <child link="r_pinky_mcp_link"/>
    <origin rpy="0.1068141484 0.19860101219666665 0.021153390173333335" xyz="-0.0098 -0.0398034 0.13514012"/>
    <axis xyz="0 1 0"/>
    <limit effort="5.0" lower="0.0" upper="1.509709802975095" velocity="1.0"/>
    <dynamics damping="0.05" friction="0.2"/>
  </joint>
  <link name="r_pinky_pip_link">
    <visual name="r_pinky_pip_link_vis">
      <origin rpy="0 0 0" xyz="0 0 0"/>
      <geometry>
        <mesh filename="package://human_description/meshes/robot_hands/m92u_hand/visual/r_pinky_pip_link.stl" scale="1e-3 1e-3 1e-3"/>
      </geometry>
      <material name="metal">
        <color rgba="0.85 0.85 0.85 1"/>
      </material>
    </visual>
    <collision name="r_pinky_pip_link_col">
      <origin rpy="0 0 0" xyz="0 0 0"/>
      <geometry>
        <mesh filename="package://human_description/meshes/robot_hands/m92u_hand/collision/r_pinky_pip_link.stl" scale="1e-3 1e-3 1e-3"/>
      </geometry>
    </collision>
    <inertial>
      <origin rpy="0 0 0" xyz="-0.0021920592 2.81739e-06 0.023240314"/>
      <mass value="0.0001"/>
      <inertia ixx="2.8856205e-06" ixy="-5.3997072e-11" ixz="-2.4954332e-07" iyy="2.8726183e-06" iyz="-9.9600212e-11" izz="3.6244504e-07"/>
    </inertial>
  </link>
  <joint name="r_pinky_pip_joint" type="revolute">
    <parent link="r_pinky_mcp_link"/>
    <child link="r_pinky_pip_link"/>
    <origin rpy="0.0 0.05016320530757778 0.0" xyz="0.0 0.0 0.0310058"/>
    <axis xyz="0 1 0"/>
    <limit effort="5.0" lower="0.0" upper="3.5831609543443586" velocity="1.0"/>
    <dynamics damping="0.05" friction="0.2"/>
    <mimic joint="r_pinky_mcp_joint" multiplier="0.9845" offset="0"/>
  </joint>
  <ros2_control name="r_hand_system" type="system">
    <hardware>
      <plugin>mujoco_ros2_control/MujocoSystem</plugin>
    </hardware>
    <joint name="r_thumb_cmc_y_joint">
      <param name="initial_position">0.0</param>
      <command_interface name="position"/>
      <state_interface name="position">
        <param name="initial_value">0.0</param>
      </state_interface>
      <state_interface name="velocity"/>
      <state_interface name="effort"/>
    </joint>
    <transmission name="r_thumb_cmc_y_transmission">
      <plugin>transmission_interface/SimpleTransmission</plugin>
      <joint name="r_thumb_cmc_y_joint" role="joint1">
        <mechanical_reduction>1.0</mechanical_reduction>
        <offset>0</offset>
      </joint>
      <actuator name="r_thumb_cmc_y_actuator" role="actuator1">
        <mechanical_reduction>1.0</mechanical_reduction>
        <offset>0</offset>
      </actuator>
    </transmission>
    <joint name="r_thumb_cmc_p_joint">
      <param name="initial_position">0.0</param>
      <command_interface name="position"/>
      <state_interface name="position">
        <param name="initial_value">0.0</param>
      </state_interface>
      <state_interface name="velocity"/>
      <state_interface name="effort"/>
    </joint>
    <transmission name="r_thumb_cmc_p_transmission">
      <plugin>transmission_interface/SimpleTransmission</plugin>
      <joint name="r_thumb_cmc_p_joint" role="joint1">
        <mechanical_reduction>1.0</mechanical_reduction>
        <offset>0</offset>
      </joint>
      <actuator name="r_thumb_cmc_p_actuator" role="actuator1">
        <mechanical_reduction>1.0</mechanical_reduction>
        <offset>0</offset>
      </actuator>
    </transmission>
    <joint name="r_thumb_mcp_joint">
      <param name="initial_position">0.0</param>
      <param name="mimic">r_thumb_cmc_p_joint</param>
      <param name="multiplier">1</param>
      <command_interface name="position"/>
      <state_interface name="position">
        <param name="initial_value">0.0</param>
      </state_interface>
      <state_interface name="velocity"/>
      <state_interface name="effort"/>
    </joint>
    <joint name="r_thumb_ip_joint">
      <param name="initial_position">0.0</param>
      <param name="mimic">r_thumb_cmc_p_joint</param>
      <param name="multiplier">1</param>
      <command_interface name="position"/>
      <state_interface name="position">
        <param name="initial_value">0.0</param>
      </state_interface>
      <state_interface name="velocity"/>
      <state_interface name="effort"/>
    </joint>
    <joint name="r_index_mcp_joint">
      <param name="initial_position">0.0</param>
      <command_interface name="position"/>
      <state_interface name="position">
        <param name="initial_value">0.0</param>
      </state_interface>
      <state_interface name="velocity"/>
      <state_interface name="effort"/>
    </joint>
    <transmission name="r_index_mcp_transmission">
      <plugin>transmission_interface/SimpleTransmission</plugin>
      <joint name="r_index_mcp_joint" role="joint1">
        <mechanical_reduction>1.0</mechanical_reduction>
        <offset>0</offset>
      </joint>
      <actuator name="r_index_mcp_actuator" role="actuator1">
        <mechanical_reduction>1.0</mechanical_reduction>
        <offset>0</offset>
      </actuator>
    </transmission>
    <joint name="r_index_pip_joint">
      <param name="initial_position">0.0</param>
      <param name="mimic">r_index_mcp_joint</param>
      <param name="multiplier">1</param>
      <command_interface name="position"/>
      <state_interface name="position">
        <param name="initial_value">0.0</param>
      </state_interface>
      <state_interface name="velocity"/>
      <state_interface name="effort"/>
    </joint>
    <joint name="r_middle_mcp_joint">
      <param name="initial_position">0.0</param>
      <command_interface name="position"/>
      <state_interface name="position">
        <param name="initial_value">0.0</param>
      </state_interface>
      <state_interface name="velocity"/>
      <state_interface name="effort"/>
    </joint>
    <transmission name="r_middle_mcp_transmission">
      <plugin>transmission_interface/SimpleTransmission</plugin>
      <joint name="r_middle_mcp_joint" role="joint1">
        <mechanical_reduction>1.0</mechanical_reduction>
        <offset>0</offset>
      </joint>
      <actuator name="r_middle_mcp_actuator" role="actuator1">
        <mechanical_reduction>1.0</mechanical_reduction>
        <offset>0</offset>
      </actuator>
    </transmission>
    <joint name="r_middle_pip_joint">
      <param name="initial_position">0.0</param>
      <param name="mimic">r_middle_mcp_joint</param>
      <param name="multiplier">1</param>
      <command_interface name="position"/>
      <state_interface name="position">
        <param name="initial_value">0.0</param>
      </state_interface>
      <state_interface name="velocity"/>
      <state_interface name="effort"/>
    </joint>
    <joint name="r_pinky_mcp_joint">
      <param name="initial_position">0.0</param>
      <command_interface name="position"/>
      <state_interface name="position">
        <param name="initial_value">0.0</param>
      </state_interface>
      <state_interface name="velocity"/>
      <state_interface name="effort"/>
    </joint>
    <transmission name="r_pinky_mcp_transmission">
      <plugin>transmission_interface/SimpleTransmission</plugin>
      <joint name="r_pinky_mcp_joint" role="joint1">
        <mechanical_reduction>1.0</mechanical_reduction>
        <offset>0</offset>
      </joint>
      <actuator name="r_pinky_mcp_actuator" role="actuator1">
        <mechanical_reduction>1.0</mechanical_reduction>
        <offset>0</offset>
      </actuator>
    </transmission>
    <joint name="r_pinky_pip_joint">
      <param name="initial_position">0.0</param>
      <param name="mimic">r_pinky_mcp_joint</param>
      <param name="multiplier">1</param>
      <command_interface name="position"/>
      <state_interface name="position">
        <param name="initial_value">0.0</param>
      </state_interface>
      <state_interface name="velocity"/>
      <state_interface name="effort"/>
    </joint>
    <joint name="r_ring_mcp_joint">
      <param name="initial_position">0.0</param>
      <command_interface name="position"/>
      <state_interface name="position">
        <param name="initial_value">0.0</param>
      </state_interface>
      <state_interface name="velocity"/>
      <state_interface name="effort"/>
    </joint>
    <transmission name="r_ring_mcp_transmission">
      <plugin>transmission_interface/SimpleTransmission</plugin>
      <joint name="r_ring_mcp_joint" role="joint1">
        <mechanical_reduction>1.0</mechanical_reduction>
        <offset>0</offset>
      </joint>
      <actuator name="r_ring_mcp_actuator" role="actuator1">
        <mechanical_reduction>1.0</mechanical_reduction>
        <offset>0</offset>
      </actuator>
    </transmission>
    <joint name="r_ring_pip_joint">
      <param name="initial_position">0.0</param>
      <param name="mimic">r_ring_mcp_joint</param>
      <param name="multiplier">1</param>
      <command_interface name="position"/>
      <state_interface name="position">
        <param name="initial_value">0.0</param>
      </state_interface>
      <state_interface name="velocity"/>
      <state_interface name="effort"/>
    </joint>
  </ros2_control>
  <mujoco>
    <compiler angle="degree" balanceinertia="true" convexhull="false" discardvisual="true" eulerseq="xyz" fusestatic="false" meshdir="../../meshes/M92UW/visual" strippath="true" texturedir="../../textures/"/>
    <option collision="all" timestep="0.001"/>
  </mujoco>
</robot>
